Workbook
Name Attendance: #REF!
Name Attendance: '[1]HK Attendance Sheet Aug''2020'!#REF!
Name dd: #REF!
Name dd: #REF!
Name dd: #REF!
Name dd: #REF!
Name dd: #REF!
Name dd: #REF!
Name Designation: #REF!
Name Designation: #REF!
Name Designation: #REF!
Name Designation: #REF!
Name Designation: #REF!
Name Designation: #REF!
Name Designation: #REF!
Name Designation: #REF!
Name Designation: #REF!
Name Designation: #REF!
Name Designation: #REF!
Name Designation: #REF!
Name Designation: #REF!
Name ff: #REF!
Name ff: #REF!
Name ff: #REF!
Name ff: #REF!
Name ff: #REF!
Name ff: #REF!
Name lljo: #REF!
Name lljo: #REF!
Name lljo: #REF!
Name lljo: #REF!
Name lljo: #REF!
Name lljo: #REF!
Name O: 'Inside Meter '!$B$1048566
Name odm: #REF!
Name odm: #REF!
Name odm: #REF!
Name odm: #REF!
Name odm: #REF!
Name odm: #REF!
Name ONDOT: #REF!
Name ONDOT: #REF!
Name ONDOT: #REF!
Name ONDOT: #REF!
Name ONDOT: #REF!
Name ONDOT: #REF!
Name ONDOT: #REF!
Name ONDOT: #REF!
Name ONDOT: #REF!
Name ONDOT: #REF!
Name ONDOT: #REF!
Name ONDOT: #REF!
Name ram: #REF!
Name ram: #REF!
Name ram: #REF!
Name ram: #REF!
Name ram: #REF!
Name ram: #REF!
Name ramji: #REF!
Name ramji: #REF!

Sheet Summary
B2: =R5&" Consumption Report Summary of "& TEXT($R$4," MMM YY") -> SOC Consumption Report Summary of Feb 26
Q3: SheetTool
Q4: Date | R4: 46054
Q5: Company Name | R5: SOC
C7: =R5&" Electricity & DG" -> SOC Electricity & DG | F7: Unit | I7: Order | J7: Total Stock | K7: Usage Stock | L7: Closing Stock | M7: Usage Amount | N7: Closing Amount | O7: Order Amount
C8: Inside Meter | D8: ELC Reading UPS Room | E8: Electricity | F8: ='Inside Meter '!F39 -> 1078 | H8: Bisleri_Consu | I8: =Bisleri_Consu!I9 -> 0 | J8: =Bisleri_Consu!N9 -> 20 | K8: =Bisleri_Consu!AT9 -> 12 | L8: =Bisleri_Consu!AU9 -> 8 | M8: =Bisleri_Consu!AV9 -> 1754.22 | N8: =Bisleri_Consu!AW9 -> 915.28 | O8: =Bisleri_Consu!AX9 -> 0
E9: HVAC | F9: ='Inside Meter '!I39 -> 7947.6 | H9: Medical_Items | I9: =Medical_Items!I27 -> 22 | J9: =Medical_Items!N27 -> 119 | K9: =Medical_Items!AT27 -> 7 | L9: =Medical_Items!AU27 -> 112 | M9: =Medical_Items!AV27 -> 494.32 | N9: =Medical_Items!AW27 -> 3265.99 | O9: =Medical_Items!AX27 -> 1879.08
D10: Reading AHU Room (Water Chiller) | E10: BTU Reading | F10: ='Inside Meter '!O39 -> 42553.86 | H10: Stationery | I10: =Stationery!H123 -> 81 | J10: =Stationery!I123 -> 1344 | K10: =Stationery!AO123 -> 183 | L10: =Stationery!AP123 -> 1181 | M10: =Stationery!AQ123 -> 4216 | N10: =Stationery!AR123 -> 16182.1 | O10: =Stationery!AS123 -> 4248
C11: OutSide Meter | D11: Mantri Office Utility MSEB and DG Meter | E11: Utility EB (KWH) | F11: ='OutSide Meter'!F38 -> 6640 | H11: HK Material | I11: ='HK Material'!I81 -> 1405 | J11: ='HK Material'!J81 -> 1984 | K11: ='HK Material'!AP81 -> 795 | L11: ='HK Material'!AQ81 -> 1189 | M11: ='HK Material'!AR81 -> 23747 | N11: ='HK Material'!AS81 -> 51402.5 | O11: ='HK Material'!AT81 -> 43843
E12: Utility DG (KWH) | F12: ='OutSide Meter'!J38 -> 80 | H12: Food Consu | I12: ='Food Consu'!J37 -> 0 | J12: =I12 -> 0 | K12: ='Food Consu'!J37 -> 0 | L12: =K12 -> 0 | M12: ='Food Consu'!N37 -> 0 | N12: ='Food Consu'!N37 -> 0 | O12: ='Food Consu'!M37 -> 0
E13: Utility EB (KVAH) | F13: ='OutSide Meter'!P38 -> 6960 | H13: Veebha Tea&Coffee | I13: ='Veebha Tea&Coffee'!I10 -> 0 | J13: ='Veebha Tea&Coffee'!N10 -> 164 | K13: ='Veebha Tea&Coffee'!AT10 -> 8 | L13: ='Veebha Tea&Coffee'!AU10 -> 156 | M13: ='Veebha Tea&Coffee'!AV10 -> 1280 | N13: ='Veebha Tea&Coffee'!AW10 -> 24960 | O13: ='Veebha Tea&Coffee'!AX10 -> 0
E14: Utility DG (KVAH) | F14: ='OutSide Meter'!T38 -> 0 | H14: Sumant Tea&Coffee | I14: ='Sumant Tea&Coffee'!I12 -> 2062 | J14: ='Sumant Tea&Coffee'!N12 -> 3153 | K14: ='Sumant Tea&Coffee'!AT12 -> 27 | L14: ='Sumant Tea&Coffee'!AU12 -> 3126 | M14: ='Sumant Tea&Coffee'!AV12 -> 4518.96 | N14: ='Sumant Tea&Coffee'!AW12 -> 19120.56 | O14: ='Sumant Tea&Coffee'!AX12 -> 12816.96
D15: Mantri Building Meter | E15: (KWH) | F15: ='OutSide Meter'!Y38 -> 89894 | H15: Toner Consu | I15: ='Toner Consu'!I15 -> 2 | J15: ='Toner Consu'!N15 -> 10 | K15: ='Toner Consu'!AT15 -> 5 | L15: ='Toner Consu'!AU15 -> 5 | M15: ='Toner Consu'!AV15 -> 4400 | N15: ='Toner Consu'!AW15 -> 6000 | O15: ='Toner Consu'!AX15 -> 2400
E16: (KVAH) | F16: ='OutSide Meter'!AB38 -> 96612 | H16: Water | I16: =Water!D36 -> 259 | J16: =Water!D36 -> 259 | K16: =Water!G36 -> 269 | L16: =Water!J41 -> 0 | M16: =K16*Water!B3 -> 9415 | N16: =Water!J41*Water!B3 -> 0 | O16: =Water!D36*Water!B3 -> 9065
D17: A - Wing Chiller Panel | E17: EB | F17: ='OutSide Meter'!AG38 -> 90.6578 | H17: Gallent SG | I17: NA | J17: NA | K17: NA | L17: NA | M17: ='Gallant SG'!AS12 -> 34721.867 | N17: ='Gallant SG'!AS12 -> 34721.867 | O17: ='Gallant SG'!AS12 -> 34721.867
E18: DG | F18: ='OutSide Meter'!AJ38 -> 278.9934 | H18: OOPL SG | I18: NA | J18: NA | K18: NA | L18: NA | M18: ='OOPL SG '!AR16 -> 88091.667 | N18: =M18 -> 88091.667 | O18: =N18 -> 88091.667
H19: Imperial HK | I19: NA | J19: NA | K19: NA | L19: NA | M19: ='Imperial HK'!AR23 -> 113108.17 | N19: =M19 -> 113108.17 | O19: =N19 -> 113108.17
H20: Extra Bill | I20: NA | J20: NA | K20: NA | L20: NA | M20: ='Extra Bills'!I99 -> 0 | N20: =M20 -> 0 | O20: =N20 -> 0

Sheet Extra Bills
B2: Company Name | C2: Expenses Type | D2: BILL DATE | E2: VENDOR NAME | F2: Office No | G2: BILL MONTH | H2: BILL NO | I2: BASIC VALUE | J2: CGST | K2: SGST | L2: TOTAL
B99: TOTAL | I99: =SUM(I6:I98) -> 0 | L99: =SUM(L6:L98) -> 0

Sheet Inside Meter 
B2: =Summary!$R$5&" Home Meter Reading "&TEXT(Summary!$R$4,"MMM YY") -> SOC Home Meter Reading Feb 26
D3: ELC Reading UPS Room | M3: Reading AHU Room (Water Chiller)
D4: Electricity | G4: HVAC | M4: BTU Reading
B5: Auto | C5: Auto | F5: Auto | I5: Auto | K5: Auto | L5: Auto | O5: Auto
B6: Date | C6: Day | D6: Opening | E6: Closening | F6: Cons | G6: Opening | H6: Closening | I6: Cons | K6: Date | L6: Day | M6: Opening | N6: Closening | O6: Cons
B7: =B8-1 -> 46053 | C7: =TEXT(B7,"DDD") -> Sat | D7: 284123 | E7: 284161.5 | F7: =E7-D7 -> 38.5 | G7: 1327218 | H7: 1327526.1 | I7: =H7-G7 -> 308.1 | K7: =K8-1 -> 46053 | L7: =TEXT(K7,"DDD") -> Sat | M7: 1425197.5 | N7: 1425762.4 | O7: =N7-M7 -> 564.92
B8: =Summary!R4 -> 46054 | C8: =TEXT(B8,"DDD") -> Sun | D8: =E7 -> 284161.5 | E8: 284212.1 | F8: =E8-D8 -> 50.6 | G8: =H7 -> 1327526.1 | H8: 1327821.7 | I8: =H8-G8 -> 295.6 | K8: =Summary!R4 -> 46054 | L8: =TEXT(K8,"DDD") -> Sun | M8: =N7 -> 1425762.4 | N8: 1425844.3 | O8: =N8-M8 -> 81.9
B9: =B8+1 -> 46055 | C9: =TEXT(B9,"DDD") -> Mon | D9: =E8 -> 284212.1 | E9: 284273.1 | F9: =E9-D9 -> 61 | G9: =H8 -> 1327821.7 | H9: 1328331.1 | I9: =H9-G9 -> 509.4 | K9: =K8+1 -> 46055 | L9: =TEXT(K9,"DDD") -> Mon | M9: =N8 -> 1425844.3 | N9: 1430437.5 | O9: =N9-M9 -> 4593.15
B10: =B9+1 -> 46056 | C10: =TEXT(B10,"DDD") -> Tue | D10: =E9 -> 284273.1 | E10: 284352.7 | F10: =E10-D10 -> 79.6 | G10: =H9 -> 1328331.1 | H10: 1328873.6 | I10: =H10-G10 -> 542.5 | K10: =K9+1 -> 46056 | L10: =TEXT(K10,"DDD") -> Tue | M10: =N9 -> 1430437.5 | N10: 1433787.1 | O10: =N10-M10 -> 3349.64
B11: =B10+1 -> 46057 | C11: =TEXT(B11,"DDD") -> Wed | D11: =E10 -> 284352.7 | E11: 284414.6 | F11: =E11-D11 -> 61.9 | G11: =H10 -> 1328873.6 | H11: 1329398.2 | I11: =H11-G11 -> 524.6 | K11: =K10+1 -> 46057 | L11: =TEXT(K11,"DDD") -> Wed | M11: =N10 -> 1433787.1 | N11: 1436046.3 | O11: =N11-M11 -> 2259.19
B12: =B11+1 -> 46058 | C12: =TEXT(B12,"DDD") -> Thu | D12: =E11 -> 284414.6 | E12: 284490.6 | F12: =E12-D12 -> 76 | G12: =H11 -> 1329398.2 | H12: 1329947.3 | I12: =H12-G12 -> 549.1 | K12: =K11+1 -> 46058 | L12: =TEXT(K12,"DDD") -> Thu | M12: =N11 -> 1436046.3 | N12: 1436576.2 | O12: =N12-M12 -> 529.93
B13: =B12+1 -> 46059 | C13: =TEXT(B13,"DDD") -> Fri | D13: =E12 -> 284490.6 | E13: 284544.1 | F13: =E13-D13 -> 53.5 | G13: =H12 -> 1329947.3 | H13: 1330433.6 | I13: =H13-G13 -> 486.3 | K13: =K12+1 -> 46059 | L13: =TEXT(K13,"DDD") -> Fri | M13: =N12 -> 1436576.2 | N13: 1437899.2 | O13: =N13-M13 -> 1322.98
B14: =B13+1 -> 46060 | C14: =TEXT(B14,"DDD") -> Sat | D14: =E13 -> 284544.1 | E14: 284598.4 | F14: =E14-D14 -> 54.3 | G14: =H13 -> 1330433.6 | H14: 1330752.6 | I14: =H14-G14 -> 319 | K14: =K13+1 -> 46060 | L14: =TEXT(K14,"DDD") -> Sat | M14: =N13 -> 1437899.2 | N14: 1438070.8 | O14: =N14-M14 -> 171.58
B15: =B14+1 -> 46061 | C15: =TEXT(B15,"DDD") -> Sun | D15: =E14 -> 284598.4 | E15: 284631.5 | F15: =E15-D15 -> 33.1 | G15: =H14 -> 1330752.6 | H15: 1330971.8 | I15: =H15-G15 -> 219.2 | K15: =K14+1 -> 46061 | L15: =TEXT(K15,"DDD") -> Sun | M15: =N14 -> 1438070.8 | N15: 1438130.8 | O15: =N15-M15 -> 59.99
B16: =B15+1 -> 46062 | C16: =TEXT(B16,"DDD") -> Mon | D16: =E15 -> 284631.5 | E16: 284712.5 | F16: =E16-D16 -> 81 | G16: =H15 -> 1330971.8 | H16: 1331525.3 | I16: =H16-G16 -> 553.5 | K16: =K15+1 -> 46062 | L16: =TEXT(K16,"DDD") -> Mon | M16: =N15 -> 1438130.8 | N16: 1444832.1 | O16: =N16-M16 -> 6701.34
B17: =B16+1 -> 46063 | C17: =TEXT(B17,"DDD") -> Tue | D17: =E16 -> 284712.5 | E17: 284776.1 | F17: =E17-D17 -> 63.6 | G17: =H16 -> 1331525.3 | H17: 1332065.3 | I17: =H17-G17 -> 540 | K17: =K16+1 -> 46063 | L17: =TEXT(K17,"DDD") -> Tue | M17: =N16 -> 1444832.1 | N17: 1449575 | O17: =N17-M17 -> 4742.83
B18: =B17+1 -> 46064 | C18: =TEXT(B18,"DDD") -> Wed | D18: =E17 -> 284776.1 | E18: 284852 | F18: =E18-D18 -> 75.9 | G18: =H17 -> 1332065.3 | H18: 1332629.3 | I18: =H18-G18 -> 564 | K18: =K17+1 -> 46064 | L18: =TEXT(K18,"DDD") -> Wed | M18: =N17 -> 1449575 | N18: 1454891.2 | O18: =N18-M18 -> 5316.19
B19: =B18+1 -> 46065 | C19: =TEXT(B19,"DDD") -> Thu | D19: =E18 -> 284852 | E19: 284922.5 | F19: =E19-D19 -> 70.5 | G19: =H18 -> 1332629.3 | H19: 1333201.2 | I19: =H19-G19 -> 571.9 | K19: =K18+1 -> 46065 | L19: =TEXT(K19,"DDD") -> Thu | M19: =N18 -> 1454891.2 | N19: 1458490.3 | O19: =N19-M19 -> 3599.14
B20: =B19+1 -> 46066 | C20: =TEXT(B20,"DDD") -> Fri | D20: =E19 -> 284922.5 | E20: 284991 | F20: =E20-D20 -> 68.5 | G20: =H19 -> 1333201.2 | H20: 1333741.3 | I20: =H20-G20 -> 540.1 | K20: =K19+1 -> 46066 | L20: =TEXT(K20,"DDD") -> Fri | M20: =N19 -> 1458490.3 | N20: 1460190.4 | O20: =N20-M20 -> 1700.12
... B24: =B23+1 -> 46070 | C24: =TEXT(B24,"DDD") -> Tue | D24: =E23 -> 285160.5 | E24: 285239.5 | F24: =E24-D24 -> 79 | G24: =H23 -> 1334918.5 | H24: 1335473.7 | I24: =H24-G24 -> 555.2 | K24: =K23+1 -> 46070 | L24: =TEXT(K24,"DDD") -> Tue | M24: =N23 -> 1464270.6 | N24: 1468316.3 | O24: =N24-M24 -> 4045.66
B25: =B24+1 -> 46071 | C25: =TEXT(B25,"DDD") -> Wed | D25: =E24 -> 285239.5 | F25: =E25-D25 -> -285239.5 | G25: =H24 -> 1335473.7 | I25: =H25-G25 -> -1335473.7 | K25: =K24+1 -> 46071 | L25: =TEXT(K25,"DDD") -> Wed | M25: =N24 -> 1468316.3 | O25: =N25-M25 -> -1468316.3
B26: =B25+1 -> 46072 | C26: =TEXT(B26,"DDD") -> Thu | D26: =E25 -> 0 | F26: =E26-D26 -> 0 | G26: =H25 -> 0 | I26: =H26-G26 -> 0 | K26: =K25+1 -> 46072 | L26: =TEXT(K26,"DDD") -> Thu | M26: =N25 -> 0 | O26: =N26-M26 -> 0
B27: =B26+1 -> 46073 | C27: =TEXT(B27,"DDD") -> Fri | D27: =E26 -> 0 | F27: =E27-D27 -> 0 | G27: =H26 -> 0 | I27: =H27-G27 -> 0 | K27: =K26+1 -> 46073 | L27: =TEXT(K27,"DDD") -> Fri | M27: =N26 -> 0 | O27: =N27-M27 -> 0
B28: =B27+1 -> 46074 | C28: =TEXT(B28,"DDD") -> Sat | D28: =E27 -> 0 | F28: =E28-D28 -> 0 | G28: =H27 -> 0 | I28: =H28-G28 -> 0 | K28: =K27+1 -> 46074 | L28: =TEXT(K28,"DDD") -> Sat | M28: =N27 -> 0 | O28: =N28-M28 -> 0
B29: =B28+1 -> 46075 | C29: =TEXT(B29,"DDD") -> Sun | D29: =E28 -> 0 | F29: =E29-D29 -> 0 | G29: =H28 -> 0 | I29: =H29-G29 -> 0 | K29: =K28+1 -> 46075 | L29: =TEXT(K29,"DDD") -> Sun | M29: =N28 -> 0 | O29: =N29-M29 -> 0
B30: =B29+1 -> 46076 | C30: =TEXT(B30,"DDD") -> Mon | D30: =E29 -> 0 | F30: =E30-D30 -> 0 | G30: =H29 -> 0 | I30: =H30-G30 -> 0 | K30: =K29+1 -> 46076 | L30: =TEXT(K30,"DDD") -> Mon | M30: =N29 -> 0 | O30: =N30-M30 -> 0
B31: =B30+1 -> 46077 | C31: =TEXT(B31,"DDD") -> Tue | D31: =E30 -> 0 | F31: =E31-D31 -> 0 | G31: =H30 -> 0 | I31: =H31-G31 -> 0 | K31: =K30+1 -> 46077 | L31: =TEXT(K31,"DDD") -> Tue | M31: =N30 -> 0 | O31: =N31-M31 -> 0
B32: =B31+1 -> 46078 | C32: =TEXT(B32,"DDD") -> Wed | D32: =E31 -> 0 | F32: =E32-D32 -> 0 | G32: =H31 -> 0 | I32: =H32-G32 -> 0 | K32: =K31+1 -> 46078 | L32: =TEXT(K32,"DDD") -> Wed | M32: =N31 -> 0 | O32: =N32-M32 -> 0
B33: =B32+1 -> 46079 | C33: =TEXT(B33,"DDD") -> Thu | D33: =E32 -> 0 | F33: =E33-D33 -> 0 | G33: =H32 -> 0 | I33: =H33-G33 -> 0 | K33: =K32+1 -> 46079 | L33: =TEXT(K33,"DDD") -> Thu | M33: =N32 -> 0 | O33: =N33-M33 -> 0
B34: =B33+1 -> 46080 | C34: =TEXT(B34,"DDD") -> Fri | D34: =E33 -> 0 | F34: =E34-D34 -> 0 | G34: =H33 -> 0 | I34: =H34-G34 -> 0 | K34: =K33+1 -> 46080 | L34: =TEXT(K34,"DDD") -> Fri | M34: =N33 -> 0 | O34: =N34-M34 -> 0
B35: =B34+1 -> 46081 | C35: =TEXT(B35,"DDD") -> Sat | D35: =E34 -> 0 | F35: =E35-D35 -> 0 | G35: =H34 -> 0 | I35: =H35-G35 -> 0 | K35: =K34+1 -> 46081 | L35: =TEXT(K35,"DDD") -> Sat | M35: =N34 -> 0 | O35: =N35-M35 -> 0
B36: =B35+1 -> 46082 | C36: =TEXT(B36,"DDD") -> Sun | D36: =E35 -> 0 | F36: =E36-D36 -> 0 | G36: =H35 -> 0 | I36: =H36-G36 -> 0 | K36: =K35+1 -> 46082 | L36: =TEXT(K36,"DDD") -> Sun | M36: =N35 -> 0 | O36: =N36-M36 -> 0
... B38: =B37+1 -> 46084 | C38: =TEXT(B38,"DDD") -> Tue | D38: =E37 -> 0 | F38: =E38-D38 -> 0 | G38: =H37 -> 0 | I38: =H38-G38 -> 0 | K38: =K37+1 -> 46084 | L38: =TEXT(K38,"DDD") -> Tue | M38: =N37 -> 0 | O38: =N38-M38 -> 0
B39: TOTAL | F39: =SUMIF(F8:F38, ">=0") -> 1078 | I39: =SUMIF(I8:I38, ">=0") -> 7947.6 | O39: =SUMIF(O8:O38, ">=0") -> 42553.86

Sheet OutSide Meter
B2: =Summary!$R$5&" MSEDCL Office Utility MSEB and DG Meter Reading "&TEXT(Summary!R$4,"MMM YY") -> SOC MSEDCL Office Utility MSEB and DG Meter Reading Feb 26 | L2: =Summary!$R$5&" MSEDCL Office Utility MSEB and DG Meter Reading "&TEXT(Summary!R4,"MMM YY") -> SOC MSEDCL Office Utility MSEB and DG Meter Reading Feb 26 | V2: =Summary!$R$5&" Building Meter Reading "&TEXT(Summary!R4,"MMM YY") -> SOC Building Meter Reading Feb 26 | AD2: ="A - Wing Chiller Panel "&TEXT(Summary!R4,"MMM YY") -> A - Wing Chiller Panel Feb 26
C3: Utility EB (KWH) | G3: Utility DG (KWH) | M3: Utility EB (KVAH) | Q3: Utility DG (KVAH) | V3: Date | W3: (KWH) | Z3: (KVAH) | AE3: EB | AH3: DG
B4: Auto | F4: Auto | J4: Auto | L4: Auto | P4: Auto | T4: Auto | V4: Auto | Y4: Auto | AB4: Auto | AD4: Auto | AG4: Auto | AJ4: Auto
B5: Date | C5: Opening | D5: Closening | E5: MF | F5: MWH Cons | G5: Opening | H5: Closening | I5: MF | J5: MWH Cons | L5: Date | M5: Opening | N5: Closening | O5: MF | P5: MWH Cons | Q5: Opening | R5: Closening | S5: MF | T5: MWH Cons | W5: Opening | X5: Closening | Y5: MWH Cons | Z5: Opening | AA5: Closening | AB5: MWH Cons | AD5: Date | AE5: Opening | AF5: Closening | AG5: MWH Cons | AH5: Opening | AI5: Closening | AJ5: MWH Cons
B6: =B7-1 -> 46053 | C6: 4689 | D6: 4694 | E6: 40 | F6: =E6*(D6-C6) -> 200 | G6: 14 | H6: 16 | I6: 40 | J6: =I6*(H6-G6) -> 80 | L6: =L7-1 -> 46053 | M6: 4819 | N6: 4824 | O6: 40 | P6: =O6*(N6-M6) -> 200 | Q6: 15 | R6: 16 | S6: 0 | T6: =S6*(R6-Q6) -> 0 | V6: =V7-1 -> 46053 | W6: 73097 | X6: 73415 | Y6: =X6-W6 -> 318 | Z6: 78880 | AA6: 79212 | AB6: =AA6-Z6 -> 332 | AD6: =AD7-1 -> 46053 | AE6: 2542.9686 | AF6: 2545.819 | AG6: =AF6-AE6 -> 2.8504 | AH6: 2107.74 | AI6: 2382.7286 | AJ6: =AI6-AH6 -> 274.9886
B7: =Summary!R4 -> 46054 | C7: =D6 -> 4694 | D7: 4699 | E7: 40 | F7: =E7*(D7-C7) -> 200 | G7: =H6 -> 16 | H7: 16 | I7: 40 | J7: =I7*(H7-G7) -> 0 | L7: =Summary!R4 -> 46054 | M7: =N6 -> 4824 | N7: 4829 | O7: 40 | P7: =O7*(N7-M7) -> 200 | Q7: =R6 -> 16 | R7: 16 | S7: 0 | T7: =S7*(R7-Q7) -> 0 | V7: =Summary!R4 -> 46054 | W7: =X6 -> 73415 | X7: 73671 | Y7: =X7-W7 -> 256 | Z7: =AA6 -> 79212 | AA7: 79480 | AB7: =AA7-Z7 -> 268 | AD7: =Summary!R4 -> 46054 | AE7: =AF6 -> 2545.819 | AF7: 2548.097 | AG7: =AF7-AE7 -> 2.278 | AH7: =AI6 -> 2382.7286 | AI7: 2382.7286 | AJ7: =AI7-AH7 -> 0
B8: =B7+1 -> 46055 | C8: =D7 -> 4699 | D8: 4705 | E8: 40 | F8: =E8*(D8-C8) -> 240 | G8: =H7 -> 16 | H8: 16 | I8: 40 | J8: =I8*(H8-G8) -> 0 | L8: =L7+1 -> 46055 | M8: =N7 -> 4829 | N8: 4835 | O8: 40 | P8: =O8*(N8-M8) -> 240 | Q8: =R7 -> 16 | R8: 16 | S8: 0 | T8: =S8*(R8-Q8) -> 0 | V8: =V7+1 -> 46055 | W8: =X7 -> 73671 | X8: 73999 | Y8: =X8-W8 -> 328 | Z8: =AA7 -> 79480 | AA8: 79822 | AB8: =AA8-Z8 -> 342 | AD8: =AD7+1 -> 46055 | AE8: =AF7 -> 2548.097 | AF8: 2551.982 | AG8: =AF8-AE8 -> 3.885 | AH8: =AI7 -> 2382.7286 | AI8: 2382.7286 | AJ8: =AI8-AH8 -> 0
B9: =B8+1 -> 46056 | C9: =D8 -> 4705 | D9: 4710 | E9: 40 | F9: =E9*(D9-C9) -> 200 | G9: =H8 -> 16 | H9: 16 | I9: 40 | J9: =I9*(H9-G9) -> 0 | L9: =L8+1 -> 46056 | M9: =N8 -> 4835 | N9: 4841 | O9: 40 | P9: =O9*(N9-M9) -> 240 | Q9: =R8 -> 16 | R9: 16 | S9: 0 | T9: =S9*(R9-Q9) -> 0 | V9: =V8+1 -> 46056 | W9: =X8 -> 73999 | X9: 74288 | Y9: =X9-W9 -> 289 | Z9: =AA8 -> 79822 | AA9: 80140 | AB9: =AA9-Z9 -> 318 | AD9: =AD8+1 -> 46056 | AE9: =AF8 -> 2551.982 | AF9: 2555.409 | AG9: =AF9-AE9 -> 3.427 | AH9: =AI8 -> 2382.7286 | AI9: 2382.7286 | AJ9: =AI9-AH9 -> 0
B10: =B9+1 -> 46057 | C10: =D9 -> 4710 | D10: 4713 | E10: 40 | F10: =E10*(D10-C10) -> 120 | G10: =H9 -> 16 | H10: 16 | I10: 40 | J10: =I10*(H10-G10) -> 0 | L10: =L9+1 -> 46057 | M10: =N9 -> 4841 | N10: 4845 | O10: 40 | P10: =O10*(N10-M10) -> 160 | Q10: =R9 -> 16 | R10: 16 | S10: 0 | T10: =S10*(R10-Q10) -> 0 | V10: =V9+1 -> 46057 | W10: =X9 -> 74288 | X10: 74683 | Y10: =X10-W10 -> 395 | Z10: =AA9 -> 80140 | AA10: 80559 | AB10: =AA10-Z10 -> 419 | AD10: =AD9+1 -> 46057 | AE10: =AF9 -> 2555.409 | AF10: 2557.4954 | AG10: =AF10-AE10 -> 2.0864 | AH10: =AI9 -> 2382.7286 | AI10: 2382.7286 | AJ10: =AI10-AH10 -> 0
B11: =B10+1 -> 46058 | C11: =D10 -> 4713 | D11: 4720 | E11: 40 | F11: =E11*(D11-C11) -> 280 | G11: =H10 -> 16 | H11: 16 | I11: 40 | J11: =I11*(H11-G11) -> 0 | L11: =L10+1 -> 46058 | M11: =N10 -> 4845 | N11: 4851 | O11: 40 | P11: =O11*(N11-M11) -> 240 | Q11: =R10 -> 16 | R11: 16 | S11: 0 | T11: =S11*(R11-Q11) -> 0 | V11: =V10+1 -> 46058 | W11: =X10 -> 74683 | X11: 75102 | Y11: =X11-W11 -> 419 | Z11: =AA10 -> 80559 | AA11: 81010 | AB11: =AA11-Z11 -> 451 | AD11: =AD10+1 -> 46058 | AE11: =AF10 -> 2557.4954 | AF11: 2561.111 | AG11: =AF11-AE11 -> 3.6156 | AH11: =AI10 -> 2382.7286 | AI11: 2382.7286 | AJ11: =AI11-AH11 -> 0
B12: =B11+1 -> 46059 | C12: =D11 -> 4720 | D12: 4728 | E12: 40 | F12: =E12*(D12-C12) -> 320 | G12: =H11 -> 16 | H12: 16 | I12: 40 | J12: =I12*(H12-G12) -> 0 | L12: =L11+1 -> 46059 | M12: =N11 -> 4851 | N12: 4859 | O12: 40 | P12: =O12*(N12-M12) -> 320 | Q12: =R11 -> 16 | R12: 16 | S12: 0 | T12: =S12*(R12-Q12) -> 0 | V12: =V11+1 -> 46059 | W12: =X11 -> 75102 | X12: 75526 | Y12: =X12-W12 -> 424 | Z12: =AA11 -> 81010 | AA12: 81466 | AB12: =AA12-Z12 -> 456 | AD12: =AD11+1 -> 46059 | AE12: =AF11 -> 2561.111 | AF12: 2564.7158 | AG12: =AF12-AE12 -> 3.6048 | AH12: =AI11 -> 2382.7286 | AI12: 2382.7286 | AJ12: =AI12-AH12 -> 0
B13: =B12+1 -> 46060 | C13: =D12 -> 4728 | D13: 4735 | E13: 40 | F13: =E13*(D13-C13) -> 280 | G13: =H12 -> 16 | H13: 16 | I13: 40 | J13: =I13*(H13-G13) -> 0 | L13: =L12+1 -> 46060 | M13: =N12 -> 4859 | N13: 4866 | O13: 40 | P13: =O13*(N13-M13) -> 280 | Q13: =R12 -> 16 | R13: 16 | S13: 0 | T13: =S13*(R13-Q13) -> 0 | V13: =V12+1 -> 46060 | W13: =X12 -> 75526 | X13: 75948 | Y13: =X13-W13 -> 422 | Z13: =AA12 -> 81466 | AA13: 82351 | AB13: =AA13-Z13 -> 885 | AD13: =AD12+1 -> 46060 | AE13: =AF12 -> 2564.7158 | AF13: 2568.4182 | AG13: =AF13-AE13 -> 3.7024 | AH13: =AI12 -> 2382.7286 | AI13: 2382.7286 | AJ13: =AI13-AH13 -> 0
B14: =B13+1 -> 46061 | C14: =D13 -> 4735 | D14: 4743 | E14: 40 | F14: =E14*(D14-C14) -> 320 | G14: =H13 -> 16 | H14: 16 | I14: 40 | J14: =I14*(H14-G14) -> 0 | L14: =L13+1 -> 46061 | M14: =N13 -> 4866 | N14: 4875 | O14: 40 | P14: =O14*(N14-M14) -> 360 | Q14: =R13 -> 16 | R14: 16 | S14: 0 | T14: =S14*(R14-Q14) -> 0 | V14: =V13+1 -> 46061 | W14: =X13 -> 75948 | X14: 76779 | Y14: =X14-W14 -> 831 | Z14: =AA13 -> 82351 | AA14: 82784 | AB14: =AA14-Z14 -> 433 | AD14: =AD13+1 -> 46061 | AE14: =AF13 -> 2568.4182 | AF14: 2572.03 | AG14: =AF14-AE14 -> 3.6118 | AH14: =AI13 -> 2382.7286 | AI14: 2382.7286 | AJ14: =AI14-AH14 -> 0
B15: =B14+1 -> 46062 | C15: =D14 -> 4743 | D15: 4750 | E15: 40 | F15: =E15*(D15-C15) -> 280 | G15: =H14 -> 16 | H15: 16 | I15: 40 | J15: =I15*(H15-G15) -> 0 | L15: =L14+1 -> 46062 | M15: =N14 -> 4875 | N15: 4883 | O15: 40 | P15: =O15*(N15-M15) -> 320 | Q15: =R14 -> 16 | R15: 16 | S15: 0 | T15: =S15*(R15-Q15) -> 0 | V15: =V14+1 -> 46062 | W15: =X14 -> 76779 | X15: 77087 | Y15: =X15-W15 -> 308 | Z15: =AA14 -> 82784 | AA15: 83133 | AB15: =AA15-Z15 -> 349 | AD15: =AD14+1 -> 46062 | AE15: =AF14 -> 2572.03 | AF15: 2575.6252 | AG15: =AF15-AE15 -> 3.5952 | AH15: =AI14 -> 2382.7286 | AI15: 2382.7286 | AJ15: =AI15-AH15 -> 0
B16: =B15+1 -> 46063 | C16: =D15 -> 4750 | D16: 4756 | E16: 40 | F16: =E16*(D16-C16) -> 240 | G16: =H15 -> 16 | H16: 16 | I16: 40 | J16: =I16*(H16-G16) -> 0 | L16: =L15+1 -> 46063 | M16: =N15 -> 4883 | N16: 4889 | O16: 40 | P16: =O16*(N16-M16) -> 240 | Q16: =R15 -> 16 | R16: 16 | S16: 0 | T16: =S16*(R16-Q16) -> 0 | V16: =V15+1 -> 46063 | W16: =X15 -> 77087 | X16: 77298 | Y16: =X16-W16 -> 211 | Z16: =AA15 -> 83133 | AA16: 83316 | AB16: =AA16-Z16 -> 183 | AD16: =AD15+1 -> 46063 | AE16: =AF15 -> 2575.6252 | AF16: 2577.9838 | AG16: =AF16-AE16 -> 2.3586 | AH16: =AI15 -> 2382.7286 | AI16: 2382.7286 | AJ16: =AI16-AH16 -> 0
B17: =B16+1 -> 46064 | C17: =D16 -> 4756 | D17: 4759 | E17: 40 | F17: =E17*(D17-C17) -> 120 | G17: =H16 -> 16 | H17: 16 | I17: 40 | J17: =I17*(H17-G17) -> 0 | L17: =L16+1 -> 46064 | M17: =N16 -> 4889 | N17: 4892 | O17: 40 | P17: =O17*(N17-M17) -> 120 | Q17: =R16 -> 16 | R17: 16 | S17: 0 | T17: =S17*(R17-Q17) -> 0 | V17: =V16+1 -> 46064 | W17: =X16 -> 77298 | X17: 77720 | Y17: =X17-W17 -> 422 | Z17: =AA16 -> 83316 | AA17: 83759 | AB17: =AA17-Z17 -> 443 | AD17: =AD16+1 -> 46064 | AE17: =AF16 -> 2577.9838 | AF17: 2579.9116 | AG17: =AF17-AE17 -> 1.9278 | AH17: =AI16 -> 2382.7286 | AI17: 2382.7286 | AJ17: =AI17-AH17 -> 0
B18: =B17+1 -> 46065 | C18: =D17 -> 4759 | D18: 4765 | E18: 40 | F18: =E18*(D18-C18) -> 240 | G18: =H17 -> 16 | H18: 16 | I18: 40 | J18: =I18*(H18-G18) -> 0 | L18: =L17+1 -> 46065 | M18: =N17 -> 4892 | N18: 4898 | O18: 40 | P18: =O18*(N18-M18) -> 240 | Q18: =R17 -> 16 | R18: 16 | S18: 0 | T18: =S18*(R18-Q18) -> 0 | V18: =V17+1 -> 46065 | W18: =X17 -> 77720 | X18: 78171 | Y18: =X18-W18 -> 451 | Z18: =AA17 -> 83759 | AA18: 84232 | AB18: =AA18-Z18 -> 473 | AD18: =AD17+1 -> 46065 | AE18: =AF17 -> 2579.9116 | AF18: 2583.906 | AG18: =AF18-AE18 -> 3.9944 | AH18: =AI17 -> 2382.7286 | AI18: 2382.7286 | AJ18: =AI18-AH18 -> 0
B19: =B18+1 -> 46066 | C19: =D18 -> 4765 | D19: 4773 | E19: 40 | F19: =E19*(D19-C19) -> 320 | G19: =H18 -> 16 | H19: 16 | I19: 40 | J19: =I19*(H19-G19) -> 0 | L19: =L18+1 -> 46066 | M19: =N18 -> 4898 | N19: 4908 | O19: 40 | P19: =O19*(N19-M19) -> 400 | Q19: =R18 -> 16 | R19: 16 | S19: 0 | T19: =S19*(R19-Q19) -> 0 | V19: =V18+1 -> 46066 | W19: =X18 -> 78171 | X19: 78635 | Y19: =X19-W19 -> 464 | Z19: =AA18 -> 84232 | AA19: 84722 | AB19: =AA19-Z19 -> 490 | AD19: =AD18+1 -> 46066 | AE19: =AF18 -> 2583.906 | AF19: 2588.1932 | AG19: =AF19-AE19 -> 4.2872 | AH19: =AI18 -> 2382.7286 | AI19: 2382.7286 | AJ19: =AI19-AH19 -> 0
... B22: =B21+1 -> 46069 | C22: =D21 -> 4788 | D22: 4796 | E22: 40 | F22: =E22*(D22-C22) -> 320 | G22: =H21 -> 16 | H22: 16 | I22: 40 | J22: =I22*(H22-G22) -> 0 | L22: =L21+1 -> 46069 | M22: =N21 -> 4922 | N22: 4930 | O22: 40 | P22: =O22*(N22-M22) -> 320 | Q22: =R21 -> 16 | R22: 16 | S22: 0 | T22: =S22*(R22-Q22) -> 0 | V22: =V21+1 -> 46069 | W22: =X21 -> 79397 | X22: 79816 | Y22: =X22-W22 -> 419 | Z22: =AA21 -> 85516 | AA22: 85967 | AB22: =AA22-Z22 -> 451 | AD22: =AD21+1 -> 46069 | AE22: =AF21 -> 2595.7468 | AF22: 2600.2302 | AG22: =AF22-AE22 -> 4.4834 | AH22: =AI21 -> 2382.7286 | AI22: 2382.7286 | AJ22: =AI22-AH22 -> 0
B23: =B22+1 -> 46070 | C23: =D22 -> 4796 | D23: 4801 | E23: 40 | F23: =E23*(D23-C23) -> 200 | G23: =H22 -> 16 | H23: 16 | I23: 40 | J23: =I23*(H23-G23) -> 0 | L23: =L22+1 -> 46070 | M23: =N22 -> 4930 | N23: 4935 | O23: 40 | P23: =O23*(N23-M23) -> 200 | Q23: =R22 -> 16 | R23: 16 | S23: 0 | T23: =S23*(R23-Q23) -> 0 | V23: =V22+1 -> 46070 | W23: =X22 -> 79816 | Y23: =X23-W23 -> -79816 | Z23: =AA22 -> 85967 | AB23: =AA23-Z23 -> -85967 | AD23: =AD22+1 -> 46070 | AE23: =AF22 -> 2600.2302 | AF23: 2603.7626 | AG23: =AF23-AE23 -> 3.5324 | AH23: =AI22 -> 2382.7286 | AI23: 2382.7286 | AJ23: =AI23-AH23 -> 0
B24: =B23+1 -> 46071 | C24: =D23 -> 4801 | D24: 4804 | E24: 40 | F24: =E24*(D24-C24) -> 120 | G24: =H23 -> 16 | H24: 16 | I24: 40 | J24: =I24*(H24-G24) -> 0 | L24: =L23+1 -> 46071 | M24: =N23 -> 4935 | N24: 4940 | O24: 40 | P24: =O24*(N24-M24) -> 200 | Q24: =R23 -> 16 | R24: 16 | S24: 0 | T24: =S24*(R24-Q24) -> 0 | V24: =V23+1 -> 46071 | W24: =X23 -> 0 | X24: 80092 | Y24: =X24-W24 -> 80092 | Z24: =AA23 -> 0 | AA24: 86285 | AB24: =AA24-Z24 -> 86285 | AD24: =AD23+1 -> 46071 | AE24: =AF23 -> 2603.7626 | AF24: 2606.125 | AG24: =AF24-AE24 -> 2.3624 | AH24: =AI23 -> 2382.7286 | AI24: 2382.7286 | AJ24: =AI24-AH24 -> 0
B25: =B24+1 -> 46072 | C25: =D24 -> 4804 | D25: 4811 | E25: 40 | F25: =E25*(D25-C25) -> 280 | G25: =H24 -> 16 | H25: 16 | I25: 40 | J25: =I25*(H25-G25) -> 0 | L25: =L24+1 -> 46072 | M25: =N24 -> 4940 | N25: 4947 | O25: 40 | P25: =O25*(N25-M25) -> 280 | Q25: =R24 -> 16 | R25: 16 | S25: 0 | T25: =S25*(R25-Q25) -> 0 | V25: =V24+1 -> 46072 | W25: =X24 -> 80092 | X25: 80532 | Y25: =X25-W25 -> 440 | Z25: =AA24 -> 86285 | AA25: 86711 | AB25: =AA25-Z25 -> 426 | AD25: =AD24+1 -> 46072 | AE25: =AF24 -> 2606.125 | AF25: 2610.2896 | AG25: =AF25-AE25 -> 4.1646 | AH25: =AI24 -> 2382.7286 | AI25: 2382.7286 | AJ25: =AI25-AH25 -> 0
B26: =B25+1 -> 46073 | C26: =D25 -> 4811 | D26: 4819 | E26: 40 | F26: =E26*(D26-C26) -> 320 | G26: =H25 -> 16 | H26: 16 | I26: 40 | J26: =I26*(H26-G26) -> 0 | L26: =L25+1 -> 46073 | M26: =N25 -> 4947 | N26: 4955 | O26: 40 | P26: =O26*(N26-M26) -> 320 | Q26: =R25 -> 16 | R26: 16 | S26: 0 | T26: =S26*(R26-Q26) -> 0 | V26: =V25+1 -> 46073 | W26: =X25 -> 80532 | X26: 80990 | Y26: =X26-W26 -> 458 | Z26: =AA25 -> 86711 | AA26: 87196 | AB26: =AA26-Z26 -> 485 | AD26: =AD25+1 -> 46073 | AE26: =AF25 -> 2610.2896 | AF26: 2614.6504 | AG26: =AF26-AE26 -> 4.3608 | AH26: =AI25 -> 2382.7286 | AI26: 2382.7286 | AJ26: =AI26-AH26 -> 0
B27: =B26+1 -> 46074 | C27: =D26 -> 4819 | D27: 4826 | E27: 40 | F27: =E27*(D27-C27) -> 280 | G27: =H26 -> 16 | H27: 16 | I27: 40 | J27: =I27*(H27-G27) -> 0 | L27: =L26+1 -> 46074 | M27: =N26 -> 4955 | N27: 4963 | O27: 40 | P27: =O27*(N27-M27) -> 320 | Q27: =R26 -> 16 | R27: 16 | S27: 0 | T27: =S27*(R27-Q27) -> 0 | V27: =V26+1 -> 46074 | W27: =X26 -> 80990 | X27: 81443 | Y27: =X27-W27 -> 453 | Z27: =AA26 -> 87196 | AA27: 87686 | AB27: =AA27-Z27 -> 490 | AD27: =AD26+1 -> 46074 | AE27: =AF26 -> 2614.6504 | AF27: 2618.82 | AG27: =AF27-AE27 -> 4.1696 | AH27: =AI26 -> 2382.7286 | AI27: 2382.7286 | AJ27: =AI27-AH27 -> 0
B28: =B27+1 -> 46075 | C28: =D27 -> 4826 | D28: 4834 | E28: 40 | F28: =E28*(D28-C28) -> 320 | G28: =H27 -> 16 | H28: 16 | I28: 40 | J28: =I28*(H28-G28) -> 0 | L28: =L27+1 -> 46075 | M28: =N27 -> 4963 | N28: 4971 | O28: 40 | P28: =O28*(N28-M28) -> 320 | Q28: =R27 -> 16 | R28: 16 | S28: 0 | T28: =S28*(R28-Q28) -> 0 | V28: =V27+1 -> 46075 | W28: =X27 -> 81443 | X28: 81888 | Y28: =X28-W28 -> 445 | Z28: =AA27 -> 87686 | AA28: 88164 | AB28: =AA28-Z28 -> 478 | AD28: =AD27+1 -> 46075 | AE28: =AF27 -> 2618.82 | AF28: 2622.95 | AG28: =AF28-AE28 -> 4.13 | AH28: =AI27 -> 2382.7286 | AI28: 2382.7286 | AJ28: =AI28-AH28 -> 0
B29: =B28+1 -> 46076 | C29: =D28 -> 4834 | D29: 4842 | E29: 40 | F29: =E29*(D29-C29) -> 320 | G29: =H28 -> 16 | H29: 16 | I29: 40 | J29: =I29*(H29-G29) -> 0 | L29: =L28+1 -> 46076 | M29: =N28 -> 4971 | N29: 4979 | O29: 40 | P29: =O29*(N29-M29) -> 320 | Q29: =R28 -> 16 | R29: 16 | S29: 0 | T29: =S29*(R29-Q29) -> 0 | V29: =V28+1 -> 46076 | W29: =X28 -> 81888 | X29: 82313 | Y29: =X29-W29 -> 425 | Z29: =AA28 -> 88164 | AA29: 88619 | AB29: =AA29-Z29 -> 455 | AD29: =AD28+1 -> 46076 | AE29: =AF28 -> 2622.95 | AF29: 2626.6646 | AG29: =AF29-AE29 -> 3.7146 | AH29: =AI28 -> 2382.7286 | AI29: 2382.7286 | AJ29: =AI29-AH29 -> 0
B30: =B29+1 -> 46077 | C30: =D29 -> 4842 | D30: 4847 | E30: 40 | F30: =E30*(D30-C30) -> 200 | G30: =H29 -> 16 | H30: 16 | I30: 40 | J30: =I30*(H30-G30) -> 0 | L30: =L29+1 -> 46077 | M30: =N29 -> 4979 | N30: 4984 | O30: 40 | P30: =O30*(N30-M30) -> 200 | Q30: =R29 -> 16 | R30: 16 | S30: 0 | T30: =S30*(R30-Q30) -> 0 | V30: =V29+1 -> 46077 | W30: =X29 -> 82313 | X30: 82640 | Y30: =X30-W30 -> 327 | Z30: =AA29 -> 88619 | AA30: 88972 | AB30: =AA30-Z30 -> 353 | AD30: =AD29+1 -> 46077 | AE30: =AF29 -> 2626.6646 | AF30: 2629.2758 | AG30: =AF30-AE30 -> 2.6112 | AH30: =AI29 -> 2382.7286 | AI30: 2386.7334 | AJ30: =AI30-AH30 -> 4.0048
B31: =B30+1 -> 46078 | C31: =D30 -> 4847 | D31: 4850 | E31: 40 | F31: =E31*(D31-C31) -> 120 | G31: =H30 -> 16 | H31: 16 | I31: 40 | J31: =I31*(H31-G31) -> 0 | L31: =L30+1 -> 46078 | M31: =N30 -> 4984 | N31: 4987 | O31: 40 | P31: =O31*(N31-M31) -> 120 | Q31: =R30 -> 16 | R31: 16 | S31: 0 | T31: =S31*(R31-Q31) -> 0 | V31: =V30+1 -> 46078 | W31: =X30 -> 82640 | X31: 82891 | Y31: =X31-W31 -> 251 | Z31: =AA30 -> 88972 | AA31: 89225 | AB31: =AA31-Z31 -> 253 | AD31: =AD30+1 -> 46078 | AE31: =AF30 -> 2629.2758 | AF31: 2631.3432 | AG31: =AF31-AE31 -> 2.0674 | AH31: =AI30 -> 2386.7334 | AI31: 2386.7334 | AJ31: =AI31-AH31 -> 0
B32: =B31+1 -> 46079 | C32: =D31 -> 4850 | D32: 4855 | E32: 40 | F32: =E32*(D32-C32) -> 200 | G32: =H31 -> 16 | H32: 16 | I32: 40 | J32: =I32*(H32-G32) -> 0 | L32: =L31+1 -> 46079 | M32: =N31 -> 4987 | N32: 4993 | O32: 40 | P32: =O32*(N32-M32) -> 240 | Q32: =R31 -> 16 | R32: 16 | S32: 0 | T32: =S32*(R32-Q32) -> 0 | V32: =V31+1 -> 46079 | W32: =X31 -> 82891 | X32: 83175 | Y32: =X32-W32 -> 284 | Z32: =AA31 -> 89225 | AA32: 89525 | AB32: =AA32-Z32 -> 300 | AD32: =AD31+1 -> 46079 | AE32: =AF31 -> 2631.3432 | AF32: 2633.6264 | AG32: =AF32-AE32 -> 2.2832 | AH32: =AI31 -> 2386.7334 | AI32: 2386.7334 | AJ32: =AI32-AH32 -> 0
B33: =B32+1 -> 46080 | C33: =D32 -> 4855 | E33: 40 | F33: =E33*(D33-C33) -> -194200 | G33: =H32 -> 16 | I33: 40 | J33: =I33*(H33-G33) -> -640 | L33: =L32+1 -> 46080 | M33: =N32 -> 4993 | O33: 40 | P33: =O33*(N33-M33) -> -199720 | Q33: =R32 -> 16 | S33: 0 | T33: =S33*(R33-Q33) -> 0 | V33: =V32+1 -> 46080 | W33: =X32 -> 83175 | Y33: =X33-W33 -> -83175 | Z33: =AA32 -> 89525 | AB33: =AA33-Z33 -> -89525 | AD33: =AD32+1 -> 46080 | AE33: =AF32 -> 2633.6264 | AG33: =AF33-AE33 -> -2633.6264 | AH33: =AI32 -> 2386.7334 | AJ33: =AI33-AH33 -> -2386.7334
B34: =B33+1 -> 46081 | C34: =D33 -> 0 | E34: 40 | F34: =E34*(D34-C34) -> 0 | G34: =H33 -> 0 | I34: 40 | J34: =I34*(H34-G34) -> 0 | L34: =L33+1 -> 46081 | M34: =N33 -> 0 | O34: 40 | P34: =O34*(N34-M34) -> 0 | Q34: =R33 -> 0 | S34: 0 | T34: =S34*(R34-Q34) -> 0 | V34: =V33+1 -> 46081 | W34: =X33 -> 0 | Y34: =X34-W34 -> 0 | Z34: =AA33 -> 0 | AB34: =AA34-Z34 -> 0 | AD34: =AD33+1 -> 46081 | AE34: =AF33 -> 0 | AG34: =AF34-AE34 -> 0 | AH34: =AI33 -> 0 | AJ34: =AI34-AH34 -> 0
B35: =B34+1 -> 46082 | C35: =D34 -> 0 | E35: 40 | F35: =E35*(D35-C35) -> 0 | G35: =H34 -> 0 | I35: 40 | J35: =I35*(H35-G35) -> 0 | L35: =L34+1 -> 46082 | M35: =N34 -> 0 | O35: 40 | P35: =O35*(N35-M35) -> 0 | Q35: =R34 -> 0 | S35: 0 | T35: =S35*(R35-Q35) -> 0 | V35: =V34+1 -> 46082 | W35: =X34 -> 0 | Y35: =X35-W35 -> 0 | Z35: =AA34 -> 0 | AB35: =AA35-Z35 -> 0 | AD35: =AD34+1 -> 46082 | AE35: =AF34 -> 0 | AG35: =AF35-AE35 -> 0 | AH35: =AI34 -> 0 | AJ35: =AI35-AH35 -> 0
B36: =B35+1 -> 46083 | C36: =D35 -> 0 | E36: 40 | F36: =E36*(D36-C36) -> 0 | G36: =H35 -> 0 | I36: 40 | J36: =I36*(H36-G36) -> 0 | L36: =L35+1 -> 46083 | M36: =N35 -> 0 | O36: 40 | P36: =O36*(N36-M36) -> 0 | Q36: =R35 -> 0 | S36: 0 | T36: =S36*(R36-Q36) -> 0 | V36: =V35+1 -> 46083 | W36: =X35 -> 0 | Y36: =X36-W36 -> 0 | Z36: =AA35 -> 0 | AB36: =AA36-Z36 -> 0 | AD36: =AD35+1 -> 46083 | AE36: =AF35 -> 0 | AG36: =AF36-AE36 -> 0 | AH36: =AI35 -> 0 | AJ36: =AI36-AH36 -> 0
B37: =B36+1 -> 46084 | C37: =D36 -> 0 | E37: 40 | F37: =E37*(D37-C37) -> 0 | G37: =H36 -> 0 | I37: 40 | J37: =I37*(H37-G37) -> 0 | L37: =L36+1 -> 46084 | M37: =N36 -> 0 | O37: 40 | P37: =O37*(N37-M37) -> 0 | Q37: =R36 -> 0 | S37: 0 | T37: =S37*(R37-Q37) -> 0 | V37: =V36+1 -> 46084 | W37: =X36 -> 0 | Y37: =X37-W37 -> 0 | Z37: =AA36 -> 0 | AB37: =AA37-Z37 -> 0 | AD37: =AD36+1 -> 46084 | AE37: =AF36 -> 0 | AG37: =AF37-AE37 -> 0 | AH37: =AI36 -> 0 | AJ37: =AI37-AH37 -> 0
B38: TOTAL | F38: =SUMIF(F6:F37, ">=0") -> 6640 | J38: =SUMIF(J6:J37, ">=0") -> 80 | P38: =SUMIF(P6:P37, ">=0") -> 6960 | T38: =SUMIF(T6:T37, ">=0") -> 0 | Y38: =SUMIF(Y6:Y37, ">=0") -> 89894 | AB38: =SUMIF(AB6:AB37, ">=0") -> 96612 | AG38: =SUMIF(AG6:AG37, ">=0") -> 90.6578 | AJ38: =SUMIF(AJ6:AJ37, ">=0") -> 278.9934

Sheet Bisleri_Consu
B2: =Summary!R5&" Bisleri Material Consumption for the Month of "& TEXT(Summary!R4," MMM YY") -> SOC Bisleri Material Consumption for the Month of Feb 26
N4: Auto | O4: =TEXT(O5,"ddd") -> Sun | P4: =TEXT(P5,"ddd") -> Mon | Q4: =TEXT(Q5,"ddd") -> Tue | R4: =TEXT(R5,"ddd") -> Wed | S4: =TEXT(S5,"ddd") -> Thu | T4: =TEXT(T5,"ddd") -> Fri | U4: =TEXT(U5,"ddd") -> Sat | V4: =TEXT(V5,"ddd") -> Sun | ... AS4: =TEXT(AS5,"ddd") -> Tue | AT4: Auto | AU4: Auto | AV4: Auto | AW4: Auto | AX4: Auto | BA4: Auto
B5: Sr. No. | C5: Vendor | D5: Particulars | E5: Brand | F5: Units | G5: Rate | H5: Opening | I5: Order | J5: Office Order 1 | K5: Office Order 2 | L5: Other Sources | M5: Remark | N5: Total Stock | O5: =Summary!R4 -> 46054 | P5: =O5+1 -> 46055 | Q5: =P5+1 -> 46056 | R5: =Q5+1 -> 46057 | S5: =R5+1 -> 46058 | T5: =S5+1 -> 46059 | U5: =T5+1 -> 46060 | V5: =U5+1 -> 46061 | W5: =V5+1 -> 46062 | ... AS5: =AR5+1 -> 46084 | AT5: Usage Stock | AU5: Closing Stock | AV5: Usage Amount | AW5: Closing Amount | AX5: Order Amount | AY5: CGST | AZ5: SGST | BA5: Order Amount With GST
B6: 1 | C6: Bisleri | D6: Bottle | E6: Bisleri | F6: 500ML | G6: 152.54 | H6: 10 | N6: =SUM(H6:L6) -> 10 | P6: 1 | Q6: 1 | S6: 1 | T6: 1 | W6: 1 | X6: 1 | Y6: 1 | Z6: 1 | AA6: 1 | AD6: 1 | AT6: =SUM(O6:AS6) -> 10 | AU6: =N6-AT6 -> 0 | AV6: =AT6*G6 -> 1525.4 | AW6: =AU6*G6 -> 0 | AX6: =I6*G6 -> 0 | AY6: 9 | AZ6: 9 | BA6: =AX6*SUM(AY6:AZ6)%+AX6 -> 0
B7: 2 | C7: Bisleri | D7: Bottle | E7: Bisleri | F7: 250 ML | G7: 114.41 | H7: 10 | N7: =SUM(H7:L7) -> 10 | P7: 1 | AA7: 1 | AT7: =SUM(O7:AS7) -> 2 | AU7: =N7-AT7 -> 8 | AV7: =AT7*G7 -> 228.82 | AW7: =AU7*G7 -> 915.28 | AX7: =I7*G7 -> 0 | BA7: =AX7*SUM(AY7:AZ7)%+AX7 -> 0
B8: 3 | N8: =SUM(H8:L8) -> 0 | AT8: =SUM(O8:AS8) -> 0 | AU8: =N8-AT8 -> 0 | AV8: =AT8*G8 -> 0 | AW8: =AU8*G8 -> 0 | AX8: =I8*G8 -> 0 | BA8: =AX8*SUM(AY8:AZ8)%+AX8 -> 0
D9: Total | H9: =SUM(H6:H8) -> 20 | I9: =SUM(I6:I8) -> 0 | N9: =SUM(N6:N8) -> 20 | O9: =SUM(O6:O8) -> 0 | P9: =SUM(P6:P8) -> 2 | Q9: =SUM(Q6:Q8) -> 1 | R9: =SUM(R6:R8) -> 0 | S9: =SUM(S6:S8) -> 1 | T9: =SUM(T6:T8) -> 1 | U9: =SUM(U6:U8) -> 0 | ... AR9: =SUM(AR6:AR8) -> 0 | AT9: =SUM(AT6:AT8) -> 12 | AU9: =SUM(AU6:AU8) -> 8 | AV9: =SUM(AV6:AV8) -> 1754.22 | AW9: =SUM(AW6:AW8) -> 915.28 | AX9: =SUM(AX6:AX8) -> 0 | AY9: =SUM(AY6:AY8) -> 9 | AZ9: =SUM(AZ6:AZ8) -> 9 | BA9: =SUM(BA6:BA8) -> 0

Sheet Medical_Items
B2: =Summary!R5&" Medical Material Consumption for the Month of "& TEXT(Summary!R4," MMM YY") -> SOC Medical Material Consumption for the Month of Feb 26
N4: Auto | O4: =TEXT(O5,"ddd") -> Sun | P4: =TEXT(P5,"ddd") -> Mon | Q4: =TEXT(Q5,"ddd") -> Tue | R4: =TEXT(R5,"ddd") -> Wed | S4: =TEXT(S5,"ddd") -> Thu | T4: =TEXT(T5,"ddd") -> Fri | U4: =TEXT(U5,"ddd") -> Sat | V4: =TEXT(V5,"ddd") -> Sun | ... AS4: =TEXT(AS5,"ddd") -> Tue | AT4: Auto | AU4: Auto | AV4: Auto | AW4: Auto | AX4: Auto | BA4: Auto
B5: Sr. No. | C5: Vendor | D5: Particulars | E5: Brand | F5: Units | G5: Rate | H5: Opening | I5: Order | J5: Office Order 1 | K5: Office Order 2 | L5: Other Sources | M5: Remark | N5: Total Stock | O5: =Summary!R4 -> 46054 | P5: =O5+1 -> 46055 | Q5: =P5+1 -> 46056 | R5: =Q5+1 -> 46057 | S5: =R5+1 -> 46058 | T5: =S5+1 -> 46059 | U5: =T5+1 -> 46060 | V5: =U5+1 -> 46061 | W5: =V5+1 -> 46062 | ... AS5: =AR5+1 -> 46084 | AT5: Usage Stock | AU5: Closing Stock | AV5: Usage Amount | AW5: Closing Amount | AX5: Order Amount | AY5: CGST | AZ5: SGST | BA5: Order Amount With GST
B6: 1 | D6: Volini Spray | E6: Volini | F6: Nos | G6: 220 | H6: 3 | I6: 6 | N6: =SUM(H6:L6) -> 9 | R6: 1 | X6: 1 | AT6: =SUM(O6:AS6) -> 2 | AU6: =N6-AT6 -> 7 | AV6: =AT6*G6 -> 440 | AW6: =AU6*G6 -> 1540 | AX6: =I6*G6 -> 1320 | AY6: 9 | AZ6: 9 | BA6: =AX6*SUM(AY6:AZ6)%+AX6 -> 1557.6
B7: 2 | D7: Cipladine Cream | F7: Nos | G7: 52.71 | H7: 1 | I7: 1 | N7: =SUM(H7:L7) -> 2 | AT7: =SUM(O7:AS7) -> 0 | AU7: =N7-AT7 -> 2 | AV7: =AT7*G7 -> 0 | AW7: =AU7*G7 -> 105.42 | AX7: =I7*G7 -> 52.71 | AY7: 9 | AZ7: 9 | BA7: =AX7*SUM(AY7:AZ7)%+AX7 -> 62.1978
B8: 3 | D8: Cipladine Powder | F8: Nos | G8: 90 | H8: 2 | N8: =SUM(H8:L8) -> 2 | AT8: =SUM(O8:AS8) -> 0 | AU8: =N8-AT8 -> 2 | AV8: =AT8*G8 -> 0 | AW8: =AU8*G8 -> 180 | AX8: =I8*G8 -> 0 | AY8: 9 | AZ8: 9 | BA8: =AX8*SUM(AY8:AZ8)%+AX8 -> 0
B9: 4 | D9: Soframycin Cream | F9: Nos | G9: 55.77 | H9: 0 | I9: 1 | N9: =SUM(H9:L9) -> 1 | AT9: =SUM(O9:AS9) -> 0 | AU9: =N9-AT9 -> 1 | AV9: =AT9*G9 -> 0 | AW9: =AU9*G9 -> 55.77 | AX9: =I9*G9 -> 55.77 | AY9: 9 | AZ9: 9 | BA9: =AX9*SUM(AY9:AZ9)%+AX9 -> 65.8086
B10: 5 | D10: Betnovate Cream | F10: Nos | G10: 23.3 | H10: 0 | N10: =SUM(H10:L10) -> 0 | AT10: =SUM(O10:AS10) -> 0 | AU10: =N10-AT10 -> 0 | AV10: =AT10*G10 -> 0 | AW10: =AU10*G10 -> 0 | AX10: =I10*G10 -> 0 | AY10: 9 | AZ10: 9 | BA10: =AX10*SUM(AY10:AZ10)%+AX10 -> 0
B11: 6 | D11: Volini Gel | E11: Volini | F11: Nos | G11: 76 | H11: 3 | N11: =SUM(H11:L11) -> 3 | AT11: =SUM(O11:AS11) -> 0 | AU11: =N11-AT11 -> 3 | AV11: =AT11*G11 -> 0 | AW11: =AU11*G11 -> 228 | AX11: =I11*G11 -> 0 | AY11: 9 | AZ11: 9 | BA11: =AX11*SUM(AY11:AZ11)%+AX11 -> 0
B12: 7 | D12: ORS Powder 20gm | F12: PKT | G12: 22.66 | H12: 22 | I12: 10 | N12: =SUM(H12:L12) -> 32 | R12: 1 | X12: 1 | AT12: =SUM(O12:AS12) -> 2 | AU12: =N12-AT12 -> 30 | AV12: =AT12*G12 -> 45.32 | AW12: =AU12*G12 -> 679.8 | AX12: =I12*G12 -> 226.6 | AY12: 9 | AZ12: 9 | BA12: =AX12*SUM(AY12:AZ12)%+AX12 -> 267.388
B13: 8 | D13: Cotton absorbent big | F13: Roll | G13: 15 | H13: 0 | N13: =SUM(H13:L13) -> 0 | AT13: =SUM(O13:AS13) -> 0 | AU13: =N13-AT13 -> 0 | AV13: =AT13*G13 -> 0 | AW13: =AU13*G13 -> 0 | AX13: =I13*G13 -> 0 | AY13: 9 | AZ13: 9 | BA13: =AX13*SUM(AY13:AZ13)%+AX13 -> 0
B14: 9 | D14: Cotton absorbent Small | F14: Nos | G14: 15 | H14: 2 | N14: =SUM(H14:L14) -> 2 | AT14: =SUM(O14:AS14) -> 0 | AU14: =N14-AT14 -> 2 | AV14: =AT14*G14 -> 0 | AW14: =AU14*G14 -> 30 | AX14: =I14*G14 -> 0 | AY14: 9 | AZ14: 9 | BA14: =AX14*SUM(AY14:AZ14)%+AX14 -> 0
B15: 10 | D15: Cotton Roll | F15: Roll | H15: 0 | N15: =SUM(H15:L15) -> 0 | AT15: =SUM(O15:AS15) -> 0 | AU15: =N15-AT15 -> 0 | AV15: =AT15*G15 -> 0 | AW15: =AU15*G15 -> 0 | AX15: =I15*G15 -> 0 | AY15: 9 | AZ15: 9 | BA15: =AX15*SUM(AY15:AZ15)%+AX15 -> 0
B16: 11 | D16: Glucon-D (Glucose) | F16: Nos | G16: 56 | H16: 2 | I16: 4 | N16: =SUM(H16:L16) -> 6 | AT16: =SUM(O16:AS16) -> 0 | AU16: =N16-AT16 -> 6 | AV16: =AT16*G16 -> 0 | AW16: =AU16*G16 -> 336 | AX16: =I16*G16 -> 224 | AY16: 9 | AZ16: 9 | BA16: =AX16*SUM(AY16:AZ16)%+AX16 -> 264.32
B17: 12 | D17: Seser | F17: Nos | H17: 0 | N17: =SUM(H17:L17) -> 0 | AT17: =SUM(O17:AS17) -> 0 | AU17: =N17-AT17 -> 0 | AV17: =AT17*G17 -> 0 | AW17: =AU17*G17 -> 0 | AX17: =I17*G17 -> 0 | AY17: 9 | AZ17: 9 | BA17: =AX17*SUM(AY17:AZ17)%+AX17 -> 0
B18: 13 | D18: Fixation Tape | F18: Nos | G18: 91 | H18: 0 | N18: =SUM(H18:L18) -> 0 | AT18: =SUM(O18:AS18) -> 0 | AU18: =N18-AT18 -> 0 | AV18: =AT18*G18 -> 0 | AW18: =AU18*G18 -> 0 | AX18: =I18*G18 -> 0 | AY18: 9 | AZ18: 9 | BA18: =AX18*SUM(AY18:AZ18)%+AX18 -> 0
B19: 14 | D19: Gauze Bandage Small | F19: Nos | H19: 10 | N19: =SUM(H19:L19) -> 10 | AT19: =SUM(O19:AS19) -> 0 | AU19: =N19-AT19 -> 10 | AV19: =AT19*G19 -> 0 | AW19: =AU19*G19 -> 0 | AX19: =I19*G19 -> 0 | AY19: 9 | AZ19: 9 | BA19: =AX19*SUM(AY19:AZ19)%+AX19 -> 0
B20: 15 | D20: Whisper choice | F20: Pkt | H20: 3 | N20: =SUM(H20:L20) -> 3 | AT20: =SUM(O20:AS20) -> 0 | AU20: =N20-AT20 -> 3 | AV20: =AT20*G20 -> 0 | AW20: =AU20*G20 -> 0 | AX20: =I20*G20 -> 0 | AY20: 9 | AZ20: 9 | BA20: =AX20*SUM(AY20:AZ20)%+AX20 -> 0
B21: 16 | D21: Hansaplast Spot (Round) | F21: Nos | G21: 2 | H21: 24 | N21: =SUM(H21:L21) -> 24 | AT21: =SUM(O21:AS21) -> 0 | AU21: =N21-AT21 -> 24 | AV21: =AT21*G21 -> 0 | AW21: =AU21*G21 -> 48 | AX21: =I21*G21 -> 0 | AY21: 9 | AZ21: 9 | BA21: =AX21*SUM(AY21:AZ21)%+AX21 -> 0
B22: 17 | D22: Hansaplast Bandage | F22: Nos | G22: 3 | H22: 24 | N22: =SUM(H22:L22) -> 24 | S22: 3 | AT22: =SUM(O22:AS22) -> 3 | AU22: =N22-AT22 -> 21 | AV22: =AT22*G22 -> 9 | AW22: =AU22*G22 -> 63 | AX22: =I22*G22 -> 0 | AY22: 9 | AZ22: 9 | BA22: =AX22*SUM(AY22:AZ22)%+AX22 -> 0
B23: 18 | D23: Dettol Small | F23: Nos | H23: 1 | N23: =SUM(H23:L23) -> 1 | AT23: =SUM(O23:AS23) -> 0 | AU23: =N23-AT23 -> 1 | AV23: =AT23*G23 -> 0 | AW23: =AU23*G23 -> 0 | AX23: =I23*G23 -> 0 | AY23: 9 | AZ23: 9 | BA23: =AX23*SUM(AY23:AZ23)%+AX23 -> 0
H24: 0 | N24: =SUM(H24:L24) -> 0 | AT24: =SUM(O24:AS24) -> 0 | AU24: =N24-AT24 -> 0 | AV24: =AT24*G24 -> 0 | AW24: =AU24*G24 -> 0 | AX24: =I24*G24 -> 0 | AY24: 9 | AZ24: 9 | BA24: =AX24*SUM(AY24:AZ24)%+AX24 -> 0
H25: 0 | N25: =SUM(H25:L25) -> 0 | AT25: =SUM(O25:AS25) -> 0 | AU25: =N25-AT25 -> 0 | AV25: =AT25*G25 -> 0 | AW25: =AU25*G25 -> 0 | AX25: =I25*G25 -> 0 | AY25: 9 | AZ25: 9 | BA25: =AX25*SUM(AY25:AZ25)%+AX25 -> 0
H26: 0 | N26: =SUM(H26:L26) -> 0 | AT26: =SUM(O26:AS26) -> 0 | AU26: =N26-AT26 -> 0 | AV26: =AT26*G26 -> 0 | AW26: =AU26*G26 -> 0 | AX26: =I26*G26 -> 0 | BA26: =AX26*SUM(AY26:AZ26)%+AX26 -> 0
D27: Total | H27: =SUM(H6:H26) -> 97 | I27: =SUM(I6:I26) -> 22 | N27: =SUM(N6:N26) -> 119 | O27: =SUM(O6:O26) -> 0 | P27: =SUM(P6:P26) -> 0 | Q27: =SUM(Q6:Q26) -> 0 | R27: =SUM(R6:R26) -> 2 | S27: =SUM(S6:S26) -> 3 | T27: =SUM(T6:T26) -> 0 | U27: =SUM(U6:U26) -> 0 | ... AR27: =SUM(AR6:AR26) -> 0 | AT27: =SUM(AT6:AT26) -> 7 | AU27: =SUM(AU6:AU26) -> 112 | AV27: =SUM(AV6:AV26) -> 494.32 | AW27: =SUM(AW6:AW26) -> 3265.99 | AX27: =SUM(AX6:AX26) -> 1879.08 | AY27: =SUM(AY6:AY26) -> 180 | AZ27: =SUM(AZ6:AZ26) -> 180 | BA27: =SUM(BA6:BA26) -> 2217.3144

Sheet Stationery
B2: =Summary!R5&" Stationary Material Consumption for the Month of "& TEXT(Summary!R4," MMM YY") -> SOC Stationary Material Consumption for the Month of Feb 26
I4: Auto | J4: =TEXT(J5,"ddd") -> Sun | K4: =TEXT(K5,"ddd") -> Mon | L4: =TEXT(L5,"ddd") -> Tue | M4: =TEXT(M5,"ddd") -> Wed | N4: =TEXT(N5,"ddd") -> Thu | O4: =TEXT(O5,"ddd") -> Fri | P4: =TEXT(P5,"ddd") -> Sat | Q4: =TEXT(Q5,"ddd") -> Sun | ... AN4: =TEXT(AN5,"ddd") -> Tue | AO4: Auto | AP4: Auto | AQ4: Auto | AR4: Auto | AS4: Auto | AV4: Auto
B5: Sr. No. | C5: Particulars | D5: Brand | E5: Units | F5: Rate | G5: Opening | H5: Order | I5: Total Stock | J5: =Summary!R4 -> 46054 | K5: =J5+1 -> 46055 | L5: =K5+1 -> 46056 | M5: =L5+1 -> 46057 | N5: =M5+1 -> 46058 | O5: =N5+1 -> 46059 | P5: =O5+1 -> 46060 | Q5: =P5+1 -> 46061 | R5: =Q5+1 -> 46062 | ... AN5: =AM5+1 -> 46084 | AO5: Usage Stock | AP5: Closing Stock | AQ5: Usage Amount | AR5: Closing Amount | AS5: Order Amount | AT5: CGST | AU5: SGST | AV5: Order Amount With GST | AW5: ACTUAL STOCK
B6: 1 | C6: Spring File | D6: Rajal/Vagad | E6: Nos. | F6: 12 | G6: 10 | I6: =G6+H6 -> 10 | AO6: =SUM(J6:AN6) -> 0 | AP6: =I6-AO6 -> 10 | AQ6: =AO6*F6 -> 0 | AR6: =AP6*F6 -> 120 | AS6: =H6*F6 -> 0 | AV6: =AS6*SUM(AT6:AU6)%+AS6 -> 0
B7: 2 | C7: White Envelop A4 Size | D7: Jemine | E7: Nos. | F7: 3.5 | G7: 25 | I7: =G7+H7 -> 25 | AO7: =SUM(J7:AN7) -> 0 | AP7: =I7-AO7 -> 25 | AQ7: =AO7*F7 -> 0 | AR7: =AP7*F7 -> 87.5 | AS7: =H7*F7 -> 0 | AV7: =AS7*SUM(AT7:AU7)%+AS7 -> 0
B8: 3 | C8: Box File | D8: Rajal/Vagad | E8: Nos. | F8: 62 | G8: 13 | I8: =G8+H8 -> 13 | M8: 2 | V8: 2 | AO8: =SUM(J8:AN8) -> 4 | AP8: =I8-AO8 -> 9 | AQ8: =AO8*F8 -> 248 | AR8: =AP8*F8 -> 558 | AS8: =H8*F8 -> 0 | AV8: =AS8*SUM(AT8:AU8)%+AS8 -> 0
B9: 4 | C9: Writing Pad No. 1 | D9: Vedant | E9: Nos. | F9: 20 | G9: 11 | H9: 10 | I9: =G9+H9 -> 21 | K9: 1 | R9: 3 | V9: 1 | AO9: =SUM(J9:AN9) -> 5 | AP9: =I9-AO9 -> 16 | AQ9: =AO9*F9 -> 100 | AR9: =AP9*F9 -> 320 | AS9: =H9*F9 -> 200 | AV9: =AS9*SUM(AT9:AU9)%+AS9 -> 200
B10: 5 | C10: Conference Pad | D10: Vedant | E10: Nos. | F10: 6.5 | G10: 16 | I10: =G10+H10 -> 16 | AO10: =SUM(J10:AN10) -> 0 | AP10: =I10-AO10 -> 16 | AQ10: =AO10*F10 -> 0 | AR10: =AP10*F10 -> 104 | AS10: =H10*F10 -> 0 | AV10: =AS10*SUM(AT10:AU10)%+AS10 -> 0
B11: 6 | C11: Cheque Envelops | D11: Jemine | E11: Nos. | F11: 1.25 | G11: 16 | I11: =G11+H11 -> 16 | AO11: =SUM(J11:AN11) -> 0 | AP11: =I11-AO11 -> 16 | AQ11: =AO11*F11 -> 0 | AR11: =AP11*F11 -> 20 | AS11: =H11*F11 -> 0 | AV11: =AS11*SUM(AT11:AU11)%+AS11 -> 0
B12: 7 | C12: Cello Tape 1" | D12: Wonder | E12: Nos. | F12: 12 | G12: 8 | H12: 5 | I12: =G12+H12 -> 13 | S12: 1 | AO12: =SUM(J12:AN12) -> 1 | AP12: =I12-AO12 -> 12 | AQ12: =AO12*F12 -> 12 | AR12: =AP12*F12 -> 144 | AS12: =H12*F12 -> 60 | AV12: =AS12*SUM(AT12:AU12)%+AS12 -> 60
B13: 8 | C13: Cello Tape 2" | D13: Wonder | E13: Nos. | F13: 24 | G13: 4 | H13: 5 | I13: =G13+H13 -> 9 | K13: 2 | S13: 1 | AO13: =SUM(J13:AN13) -> 3 | AP13: =I13-AO13 -> 6 | AQ13: =AO13*F13 -> 72 | AR13: =AP13*F13 -> 144 | AS13: =H13*F13 -> 120 | AV13: =AS13*SUM(AT13:AU13)%+AS13 -> 120
B14: 9 | C14: Calculator | E14: Nos. | G14: 1 | I14: =G14+H14 -> 1 | AO14: =SUM(J14:AN14) -> 0 | AP14: =I14-AO14 -> 1 | AQ14: =AO14*F14 -> 0 | AR14: =AP14*F14 -> 0 | AS14: =H14*F14 -> 0
B15: 10 | C15: Natraj Ball Pen | D15: Natraj | E15: Nos. | F15: 2.9 | G15: 33 | H15: 20 | I15: =G15+H15 -> 53 | K15: 5 | M15: 3 | R15: 3 | AO15: =SUM(J15:AN15) -> 11 | AP15: =I15-AO15 -> 42 | AQ15: =AO15*F15 -> 31.9 | AR15: =AP15*F15 -> 121.8 | AS15: =H15*F15 -> 58 | AV15: =AS15*SUM(AT15:AU15)%+AS15 -> 58
B16: 11 | C16: Foam tape new brand | D16: Wonder | E16: Nos. | F16: 35 | G16: 3 | I16: =G16+H16 -> 3 | AO16: =SUM(J16:AN16) -> 0 | AP16: =I16-AO16 -> 3 | AQ16: =AO16*F16 -> 0 | AR16: =AP16*F16 -> 105 | AS16: =H16*F16 -> 0 | AV16: =AS16*SUM(AT16:AU16)%+AS16 -> 0
B17: 12 | C17: File Tag | D17: Local Brand | E17: Pkt | F17: 80 | G17: 0 | I17: =G17+H17 -> 0 | AO17: =SUM(J17:AN17) -> 0 | AP17: =I17-AO17 -> 0 | AQ17: =AO17*F17 -> 0 | AR17: =AP17*F17 -> 0 | AS17: =H17*F17 -> 0 | AV17: =AS17*SUM(AT17:AU17)%+AS17 -> 0
B18: 13 | C18: White Board Markar Blue | D18: Camlin | E18: Nos. | F18: 21 | G18: 19 | I18: =G18+H18 -> 19 | AO18: =SUM(J18:AN18) -> 0 | AP18: =I18-AO18 -> 19 | AQ18: =AO18*F18 -> 0 | AR18: =AP18*F18 -> 399 | AS18: =H18*F18 -> 0 | AV18: =AS18*SUM(AT18:AU18)%+AS18 -> 0
B19: 14 | C19: White Board Markar Black | D19: Camlin | E19: Nos. | F19: 21 | G19: 20 | I19: =G19+H19 -> 20 | AO19: =SUM(J19:AN19) -> 0 | AP19: =I19-AO19 -> 20 | AQ19: =AO19*F19 -> 0 | AR19: =AP19*F19 -> 420 | AS19: =H19*F19 -> 0 | AV19: =AS19*SUM(AT19:AU19)%+AS19 -> 0
B20: 15 | C20: White Board Markar Red | D20: Camlin | E20: Nos. | F20: 21 | G20: 10 | I20: =G20+H20 -> 10 | AO20: =SUM(J20:AN20) -> 0 | AP20: =I20-AO20 -> 10 | AQ20: =AO20*F20 -> 0 | AR20: =AP20*F20 -> 210 | AS20: =H20*F20 -> 0 | AV20: =AS20*SUM(AT20:AU20)%+AS20 -> 0
B21: 16 | C21: Paint Marker | D21: Camlin | E21: Nos. | F21: 60 | G21: 0 | I21: =G21+H21 -> 0 | AO21: =SUM(J21:AN21) -> 0 | AP21: =I21-AO21 -> 0 | AQ21: =AO21*F21 -> 0 | AR21: =AP21*F21 -> 0 | AS21: =H21*F21 -> 0 | AV21: =AS21*SUM(AT21:AU21)%+AS21 -> 0
B22: 17 | C22: Permanent Marker | D22: Camlin | E22: Nos. | F22: 17.5 | G22: 6 | I22: =G22+H22 -> 6 | K22: 1 | AO22: =SUM(J22:AN22) -> 1 | AP22: =I22-AO22 -> 5 | AQ22: =AO22*F22 -> 17.5 | AR22: =AP22*F22 -> 87.5 | AS22: =H22*F22 -> 0 | AV22: =AS22*SUM(AT22:AU22)%+AS22 -> 0
B23: 18 | C23: Stapler No. 10 | D23: Kangaro | E23: Nos. | F23: 38 | G23: 4 | I23: =G23+H23 -> 4 | AO23: =SUM(J23:AN23) -> 0 | AP23: =I23-AO23 -> 4 | AQ23: =AO23*F23 -> 0 | AR23: =AP23*F23 -> 152 | AS23: =H23*F23 -> 0 | AV23: =AS23*SUM(AT23:AU23)%+AS23 -> 0
B24: 19 | C24: Staplar Pin Small | D24: Kangaro | E24: Box | F24: 120 | G24: 26 | I24: =G24+H24 -> 26 | AO24: =SUM(J24:AN24) -> 0 | AP24: =I24-AO24 -> 26 | AQ24: =AO24*F24 -> 0 | AR24: =AP24*F24 -> 3120 | AS24: =H24*F24 -> 0 | AV24: =AS24*SUM(AT24:AU24)%+AS24 -> 0
B25: 20 | C25: Glue Stic 8 gms | D25: Camlin | E25: Nos. | F25: 18 | G25: 3 | I25: =G25+H25 -> 3 | AO25: =SUM(J25:AN25) -> 0 | AP25: =I25-AO25 -> 3 | AQ25: =AO25*F25 -> 0 | AR25: =AP25*F25 -> 54 | AS25: =H25*F25 -> 0 | AV25: =AS25*SUM(AT25:AU25)%+AS25 -> 0
B26: 21 | C26: White Board Duster | D26: Prime | E26: Nos. | F26: 45 | G26: 10 | I26: =G26+H26 -> 10 | AO26: =SUM(J26:AN26) -> 0 | AP26: =I26-AO26 -> 10 | AQ26: =AO26*F26 -> 0 | AR26: =AP26*F26 -> 450 | AS26: =H26*F26 -> 0 | AV26: =AS26*SUM(AT26:AU26)%+AS26 -> 0
B27: 22 | C27: "U"Clip 26 mm | D27: Luxury | E27: Box | F27: 10 | G27: 6 | I27: =G27+H27 -> 6 | AO27: =SUM(J27:AN27) -> 0 | AP27: =I27-AO27 -> 6 | AQ27: =AO27*F27 -> 0 | AR27: =AP27*F27 -> 60 | AS27: =H27*F27 -> 0 | AV27: =AS27*SUM(AT27:AU27)%+AS27 -> 0
B28: 23 | C28: "V"Clip | D28: Luxury | E28: Box | F28: 9 | G28: 0 | I28: =G28+H28 -> 0 | AO28: =SUM(J28:AN28) -> 0 | AP28: =I28-AO28 -> 0 | AQ28: =AO28*F28 -> 0 | AR28: =AP28*F28 -> 0 | AS28: =H28*F28 -> 0 | AV28: =AS28*SUM(AT28:AU28)%+AS28 -> 0
B29: 24 | C29: Sharpener | D29: Natraj | E29: Nos. | F29: 2.8 | G29: 2 | I29: =G29+H29 -> 2 | AO29: =SUM(J29:AN29) -> 0 | AP29: =I29-AO29 -> 2 | AQ29: =AO29*F29 -> 0 | AR29: =AP29*F29 -> 5.6 | AS29: =H29*F29 -> 0 | AV29: =AS29*SUM(AT29:AU29)%+AS29 -> 0
B30: 25 | C30: Eraser | D30: Natraj | E30: Nos. | F30: 2.8 | G30: 6 | I30: =G30+H30 -> 6 | K30: 2 | AO30: =SUM(J30:AN30) -> 2 | AP30: =I30-AO30 -> 4 | AQ30: =AO30*F30 -> 5.6 | AR30: =AP30*F30 -> 11.2 | AS30: =H30*F30 -> 0 | AV30: =AS30*SUM(AT30:AU30)%+AS30 -> 0
B31: 26 | C31: Sketch Pen | D31: Pikpens | E31: Pkt | F31: 22 | G31: 1 | I31: =G31+H31 -> 1 | AO31: =SUM(J31:AN31) -> 0 | AP31: =I31-AO31 -> 1 | AQ31: =AO31*F31 -> 0 | AR31: =AP31*F31 -> 22 | AS31: =H31*F31 -> 0 | AV31: =AS31*SUM(AT31:AU31)%+AS31 -> 0
B32: 27 | C32: Post it Pad 3*3 | D32: Past it | E32: Nos. | F32: 28 | G32: 10 | I32: =G32+H32 -> 10 | M32: 1 | AO32: =SUM(J32:AN32) -> 1 | AP32: =I32-AO32 -> 9 | AQ32: =AO32*F32 -> 28 | AR32: =AP32*F32 -> 252 | AS32: =H32*F32 -> 0 | AV32: =AS32*SUM(AT32:AU32)%+AS32 -> 0
B33: 28 | C33: Binder Clip Big 32 mm | D33: Gorilla/Music | E33: Box. | F33: 35 | G33: 15 | I33: =G33+H33 -> 15 | Y33: 1 | AO33: =SUM(J33:AN33) -> 1 | AP33: =I33-AO33 -> 14 | AQ33: =AO33*F33 -> 35 | AR33: =AP33*F33 -> 490 | AS33: =H33*F33 -> 0 | AV33: =AS33*SUM(AT33:AU33)%+AS33 -> 0
B34: 29 | C34: Binder Clip 19 mm | D34: Gorilla/Music | E34: Nos. | F34: 20 | G34: 2 | I34: =G34+H34 -> 2 | Y34: 1 | AO34: =SUM(J34:AN34) -> 1 | AP34: =I34-AO34 -> 1 | AQ34: =AO34*F34 -> 20 | AR34: =AP34*F34 -> 20 | AS34: =H34*F34 -> 0 | AV34: =AS34*SUM(AT34:AU34)%+AS34 -> 0
B35: 30 | C35: Liuon Pins | D35: Lion/Leo | E35: Box | F35: 18 | G35: 4 | I35: =G35+H35 -> 4 | AO35: =SUM(J35:AN35) -> 0 | AP35: =I35-AO35 -> 4 | AQ35: =AO35*F35 -> 0 | AR35: =AP35*F35 -> 72 | AS35: =H35*F35 -> 0 | AV35: =AS35*SUM(AT35:AU35)%+AS35 -> 0
B36: 31 | C36: Push Pin | D36: Luxury | E36: Box | F36: 35 | G36: 2 | I36: =G36+H36 -> 2 | AO36: =SUM(J36:AN36) -> 0 | AP36: =I36-AO36 -> 2 | AQ36: =AO36*F36 -> 0 | AR36: =AP36*F36 -> 70 | AS36: =H36*F36 -> 0 | AV36: =AS36*SUM(AT36:AU36)%+AS36 -> 0
B37: 32 | C37: Stamp Pad Blue | D37: Camlin | E37: Nos. | F37: 38 | G37: 3 | I37: =G37+H37 -> 3 | AO37: =SUM(J37:AN37) -> 0 | AP37: =I37-AO37 -> 3 | AQ37: =AO37*F37 -> 0 | AR37: =AP37*F37 -> 114 | AS37: =H37*F37 -> 0 | AV37: =AS37*SUM(AT37:AU37)%+AS37 -> 0
B38: 33 | C38: Cutter Big | D38: Gorilla/Music | E38: Nos. | F38: 18 | G38: 1 | I38: =G38+H38 -> 1 | AO38: =SUM(J38:AN38) -> 0 | AP38: =I38-AO38 -> 1 | AQ38: =AO38*F38 -> 0 | AR38: =AP38*F38 -> 18 | AS38: =H38*F38 -> 0 | AV38: =AS38*SUM(AT38:AU38)%+AS38 -> 0
B39: 34 | C39: Red Adhesive Tape Double Side | D39: Local Brand | E39: Nos. | F39: 360 | G39: 0 | I39: =G39+H39 -> 0 | AO39: =SUM(J39:AN39) -> 0 | AP39: =I39-AO39 -> 0 | AQ39: =AO39*F39 -> 0 | AR39: =AP39*F39 -> 0 | AS39: =H39*F39 -> 0 | AV39: =AS39*SUM(AT39:AU39)%+AS39 -> 0
B40: 35 | C40: Fevicol Bottle Small | D40: Pidilite | E40: Nos. | F40: 29 | G40: 2 | I40: =G40+H40 -> 2 | AO40: =SUM(J40:AN40) -> 0 | AP40: =I40-AO40 -> 2 | AQ40: =AO40*F40 -> 0 | AR40: =AP40*F40 -> 58 | AS40: =H40*F40 -> 0 | AV40: =AS40*SUM(AT40:AU40)%+AS40 -> 0
B41: 36 | C41: Stamp Ink | D41: Camlin | E41: Bottle | F41: 28 | G41: 2 | I41: =G41+H41 -> 2 | AO41: =SUM(J41:AN41) -> 0 | AP41: =I41-AO41 -> 2 | AQ41: =AO41*F41 -> 0 | AR41: =AP41*F41 -> 56 | AS41: =H41*F41 -> 0 | AV41: =AS41*SUM(AT41:AU41)%+AS41 -> 0
B42: 37 | C42: Stapler Pin Big | D42: Kangaro | E42: Box | F42: 16 | G42: 11 | I42: =G42+H42 -> 11 | AO42: =SUM(J42:AN42) -> 0 | AP42: =I42-AO42 -> 11 | AQ42: =AO42*F42 -> 0 | AR42: =AP42*F42 -> 176 | AS42: =H42*F42 -> 0 | AV42: =AS42*SUM(AT42:AU42)%+AS42 -> 0
...

Sheet HK Material
B2: =Summary!R5&" House Keeping Material Consumption of "& TEXT(Summary!R4," MMM YY") -> SOC House Keeping Material Consumption of Feb 26
J4: Auto | K4: =TEXT(K5,"ddd") -> Sun | L4: =TEXT(L5,"ddd") -> Mon | M4: =TEXT(M5,"ddd") -> Tue | N4: =TEXT(N5,"ddd") -> Wed | O4: =TEXT(O5,"ddd") -> Thu | P4: =TEXT(P5,"ddd") -> Fri | Q4: =TEXT(Q5,"ddd") -> Sat | R4: =TEXT(R5,"ddd") -> Sun | ... AO4: =TEXT(AO5,"ddd") -> Tue | AP4: Auto | AQ4: Auto | AR4: Auto | AS4: Auto | AT4: Auto | AW4: Auto
B5: Sr. No. | C5: Vendor | D5: Particulars | E5: Brand | F5: Units | G5: Rate | H5: Opening | I5: Order | J5: Total Stock | K5: =Summary!R4 -> 46054 | L5: =K5+1 -> 46055 | M5: =L5+1 -> 46056 | N5: =M5+1 -> 46057 | O5: =N5+1 -> 46058 | P5: =O5+1 -> 46059 | Q5: =P5+1 -> 46060 | R5: =Q5+1 -> 46061 | S5: =R5+1 -> 46062 | ... AO5: =AN5+1 -> 46084 | AP5: Usage Stock | AQ5: Closing Stock | AR5: Usage Amount | AS5: Closing Amount | AT5: Order Amount | AU5: CGST | AV5: SGST | AW5: Order Amount With GST | AX5: ACTUAL STOCK
B6: 1 | C6: Maple Solution | D6: Handwash | E6: 5ltr | F6: Nos. | G6: 350 | H6: 1 | I6: 1 | J6: =H6+I6 -> 2 | R6: 1 | AP6: =SUM(K6:AO6) -> 1 | AQ6: =J6-AP6 -> 1 | AR6: =AP6*G6 -> 350 | AS6: =AQ6*G6 -> 350 | AT6: =I6*G6 -> 350 | AW6: =AT6*SUM(AU6:AV6)%+AT6 -> 350
B7: 2 | C7: Maple Solution | D7: Dish Wash Liquid | E7: Vim | F7: Nos.(500 ml) | G7: 90 | H7: 3 | I7: 2 | J7: =H7+I7 -> 5 | L7: 1 | AP7: =SUM(K7:AO7) -> 1 | AQ7: =J7-AP7 -> 4 | AR7: =AP7*G7 -> 90 | AS7: =AQ7*G7 -> 360 | AT7: =I7*G7 -> 180 | AW7: =AT7*SUM(AU7:AV7)%+AT7 -> 180
B8: 3 | C8: Maple Solution | D8: Vim Bar | E8: vim | F8: Nos. | G8: 18 | H8: 3 | J8: =H8+I8 -> 3 | Z8: 1 | AP8: =SUM(K8:AO8) -> 1 | AQ8: =J8-AP8 -> 2 | AR8: =AP8*G8 -> 18 | AS8: =AQ8*G8 -> 36 | AT8: =I8*G8 -> 0 | AW8: =AT8*SUM(AU8:AV8)%+AT8 -> 0
B9: 4 | C9: Maple Solution | D9: Nirama Powder | E9: Wheel | F9: Kg. | G9: 65 | H9: 3 | J9: =H9+I9 -> 3 | AP9: =SUM(K9:AO9) -> 0 | AQ9: =J9-AP9 -> 3 | AR9: =AP9*G9 -> 0 | AS9: =AQ9*G9 -> 195 | AT9: =I9*G9 -> 0 | AW9: =AT9*SUM(AU9:AV9)%+AT9 -> 0
B10: 5 | C10: Maple Solution | D10: Scrub Pad | E10: Local Brand | F10: Nos. | G10: 9 | H10: 7 | J10: =H10+I10 -> 7 | O10: 1 | AP10: =SUM(K10:AO10) -> 1 | AQ10: =J10-AP10 -> 6 | AR10: =AP10*G10 -> 9 | AS10: =AQ10*G10 -> 54 | AT10: =I10*G10 -> 0 | AW10: =AT10*SUM(AU10:AV10)%+AT10 -> 0
B11: 6 | C11: Maple Solution | D11: Garbage Bag (19*21) | E11: A1 | F11: Pkt -30 NOS | G11: 40 | H11: 22 | J11: =H11+I11 -> 22 | O11: 1 | AB11: 1 | AP11: =SUM(K11:AO11) -> 2 | AQ11: =J11-AP11 -> 20 | AR11: =AP11*G11 -> 80 | AS11: =AQ11*G11 -> 800 | AT11: =I11*G11 -> 0 | AW11: =AT11*SUM(AU11:AV11)%+AT11 -> 0
B12: 7 | C12: Maple Solution | D12: Garbage Bag Big | E12: Citi Clean | F12: Pkt -10 NOS | G12: 70 | H12: 10 | I12: 10 | J12: =H12+I12 -> 20 | M12: 1 | N12: 1 | Q12: 1 | S12: 1 | AA12: 1 | AP12: =SUM(K12:AO12) -> 5 | AQ12: =J12-AP12 -> 15 | AR12: =AP12*G12 -> 350 | AS12: =AQ12*G12 -> 1050 | AT12: =I12*G12 -> 700 | AW12: =AT12*SUM(AU12:AV12)%+AT12 -> 700
B13: 8 | C13: Maple Solution | D13: Yellow Duster | E13: Local Brand | F13: Pcs. | G13: 17 | H13: 3 | J13: =H13+I13 -> 3 | AP13: =SUM(K13:AO13) -> 0 | AQ13: =J13-AP13 -> 3 | AR13: =AP13*G13 -> 0 | AS13: =AQ13*G13 -> 51 | AT13: =I13*G13 -> 0 | AW13: =AT13*SUM(AU13:AV13)%+AT13 -> 0
B14: 9 | C14: Maple Solution | D14: Checks Duster | E14: Local Brand | F14: Pcs. | G14: 11 | H14: 6 | J14: =H14+I14 -> 6 | AP14: =SUM(K14:AO14) -> 0 | AQ14: =J14-AP14 -> 6 | AR14: =AP14*G14 -> 0 | AS14: =AQ14*G14 -> 66 | AT14: =I14*G14 -> 0 | AW14: =AT14*SUM(AU14:AV14)%+AT14 -> 0
B15: 10 | C15: Maple Solution | D15: Glass Duster | E15: Local Brand | F15: Pcs. | G15: 12 | H15: 4 | J15: =H15+I15 -> 4 | AP15: =SUM(K15:AO15) -> 0 | AQ15: =J15-AP15 -> 4 | AR15: =AP15*G15 -> 0 | AS15: =AQ15*G15 -> 48 | AT15: =I15*G15 -> 0 | AW15: =AT15*SUM(AU15:AV15)%+AT15 -> 0
B16: 11 | C16: Maple Solution | D16: Dish Cleaner Duster | E16: Scotch | F16: Pcs. | G16: 40 | H16: 8 | J16: =H16+I16 -> 8 | AP16: =SUM(K16:AO16) -> 0 | AQ16: =J16-AP16 -> 8 | AR16: =AP16*G16 -> 0 | AS16: =AQ16*G16 -> 320 | AT16: =I16*G16 -> 0 | AW16: =AT16*SUM(AU16:AV16)%+AT16 -> 0
B17: 12 | C17: Maple Solution | D17: Wiper (Glass) Steel | E17: Local Brand | F17: Pcs. | G17: 240 | H17: 1 | J17: =H17+I17 -> 1 | AP17: =SUM(K17:AO17) -> 0 | AQ17: =J17-AP17 -> 1 | AR17: =AP17*G17 -> 0 | AS17: =AQ17*G17 -> 240 | AT17: =I17*G17 -> 0 | AW17: =AT17*SUM(AU17:AV17)%+AT17 -> 0
B18: 13 | C18: Maple Solution | D18: Soft Broom | E18: Music | F18: Nos. | G18: 85 | H18: 0 | J18: =H18+I18 -> 0 | AP18: =SUM(K18:AO18) -> 0 | AQ18: =J18-AP18 -> 0 | AR18: =AP18*G18 -> 0 | AS18: =AQ18*G18 -> 0 | AT18: =I18*G18 -> 0 | AW18: =AT18*SUM(AU18:AV18)%+AT18 -> 0
B19: 14 | C19: Maple Solution | D19: Collin | E19: Collin | F19: Nos. | G19: 72 | H19: 0 | I19: 4 | J19: =H19+I19 -> 4 | Z19: 1 | AP19: =SUM(K19:AO19) -> 1 | AQ19: =J19-AP19 -> 3 | AR19: =AP19*G19 -> 72 | AS19: =AQ19*G19 -> 216 | AT19: =I19*G19 -> 288 | AW19: =AT19*SUM(AU19:AV19)%+AT19 -> 288
B20: 15 | C20: Maple Solution | D20: Wet Mop Refill Cotton | E20: Taj | F20: Nos. | G20: 85 | H20: 2 | J20: =H20+I20 -> 2 | AP20: =SUM(K20:AO20) -> 0 | AQ20: =J20-AP20 -> 2 | AR20: =AP20*G20 -> 0 | AS20: =AQ20*G20 -> 170 | AT20: =I20*G20 -> 0 | AW20: =AT20*SUM(AU20:AV20)%+AT20 -> 0
B21: 16 | C21: Maple Solution | D21: Dry Mop Refill | E21: Taj | F21: Nos. | G21: 85 | H21: 12 | J21: =H21+I21 -> 12 | AP21: =SUM(K21:AO21) -> 0 | AQ21: =J21-AP21 -> 12 | AR21: =AP21*G21 -> 0 | AS21: =AQ21*G21 -> 1020 | AT21: =I21*G21 -> 0 | AW21: =AT21*SUM(AU21:AV21)%+AT21 -> 0
B22: 17 | C22: Maple Solution | D22: R6 | E22: Taski | F22: Can (5 Ltr.) | G22: 640 | H22: 1 | I22: 1 | J22: =H22+I22 -> 2 | AP22: =SUM(K22:AO22) -> 0 | AQ22: =J22-AP22 -> 2 | AR22: =AP22*G22 -> 0 | AS22: =AQ22*G22 -> 1280 | AT22: =I22*G22 -> 640 | AW22: =AT22*SUM(AU22:AV22)%+AT22 -> 640
B23: 18 | C23: Maple Solution | D23: R2 | E23: Taski | F23: Can (5 Ltr.) | G23: 780 | H23: 2 | J23: =H23+I23 -> 2 | AP23: =SUM(K23:AO23) -> 0 | AQ23: =J23-AP23 -> 2 | AR23: =AP23*G23 -> 0 | AS23: =AQ23*G23 -> 1560 | AT23: =I23*G23 -> 0 | AW23: =AT23*SUM(AU23:AV23)%+AT23 -> 0
B24: 19 | C24: Maple Solution | D24: Premier Facial Tissue | E24: Premier | F24: Box | G24: 62 | H24: 8 | I24: 25 | J24: =H24+I24 -> 33 | L24: 4 | T24: 4 | Z24: 1 | AP24: =SUM(K24:AO24) -> 9 | AQ24: =J24-AP24 -> 24 | AR24: =AP24*G24 -> 558 | AS24: =AQ24*G24 -> 1488 | AT24: =I24*G24 -> 1550 | AW24: =AT24*SUM(AU24:AV24)%+AT24 -> 1550
B25: 20 | C25: Maple Solution | D25: Hand Tissue | E25: Prince | F25: Pkt | G25: 24 | H25: 14 | I25: 30 | J25: =H25+I25 -> 44 | L25: 3 | M25: 1 | O25: 2 | P25: 1 | S25: 2 | T25: 4 | W25: 1 | Z25: 3 | AP25: =SUM(K25:AO25) -> 17 | AQ25: =J25-AP25 -> 27 | AR25: =AP25*G25 -> 408 | AS25: =AQ25*G25 -> 648 | AT25: =I25*G25 -> 720 | AW25: =AT25*SUM(AU25:AV25)%+AT25 -> 720
B26: 21 | C26: Maple Solution | D26: Carpet Brush | E26: Local Brand | F26: Nos. | G26: 65 | H26: 3 | J26: =H26+I26 -> 3 | AP26: =SUM(K26:AO26) -> 0 | AQ26: =J26-AP26 -> 3 | AR26: =AP26*G26 -> 0 | AS26: =AQ26*G26 -> 195 | AT26: =I26*G26 -> 0 | AW26: =AT26*SUM(AU26:AV26)%+AT26 -> 0
